Workbook

Sheet Sheet1
A1: Модель | B1: КОД ТН ВЭД | C1: Прочее | D1: количество | E1: цена за шт | F1: стоимость | G1: наименование | H1: количество мест | I1: код упаковки грузового места | J1: производитель | K1: страна происхождения | L1: Марка | M1: Товарный знак | N1: ед. измерения | O1: общий вес нетто по упаковочному | P1: БРУТТО общий
A2: КИВ-125 | B2: 8481309908 | D2: 1000 | E2: 13.6 | F2: =E2*D2 -> 13600 | G2: КИВ-125 -клапан инфильтрации воздуха | H2: 2 | I2: CT | J2: Ningbo ZENTEC Air Conditioning & Refrigeration Co., Ltd | K2: Китай | L2: отсутствует | M2: отсутствует | N2: шт | O2: 312.5 | P2: 383
B3: 8481309908 | D3: 1 | E3: 2990 | F3: =E3*D3 -> 2990 | H3: 1 | I3: CT | J3: Ningbo ZENTEC Air Conditioning & Refrigeration Co., Ltd | K3: Китай | L3: отсутствует | M3: отсутствует | N3: шт
B4: 8481309908 | D4: 1 | E4: 2340 | F4: =E4*D4 -> 2340 | H4: 1 | I4: CT | J4: Ningbo ZENTEC Air Conditioning & Refrigeration Co., Ltd | K4: Китай | L4: отсутствует | M4: отсутствует | N4: шт
B5: 8481309908 | D5: 1 | E5: 2380 | F5: =E5*D5 -> 2380 | H5: 1 | I5: CT | J5: Ningbo ZENTEC Air Conditioning & Refrigeration Co., Ltd | K5: Китай | L5: отсутствует | M5: отсутствует | N5: шт
B6: 8481309908 | D6: 1 | E6: 2340 | F6: =E6*D6 -> 2340 | H6: 1 | I6: CT | J6: Ningbo ZENTEC Air Conditioning & Refrigeration Co., Ltd | K6: Китай | L6: отсутствует | M6: отсутствует | N6: шт
B7: 8481309908 | D7: 1 | E7: 3340 | F7: =E7*D7 -> 3340 | H7: 1 | I7: CT | J7: Ningbo ZENTEC Air Conditioning & Refrigeration Co., Ltd | K7: Китай | L7: отсутствует | M7: отсутствует | N7: шт
B8: 8481309908 | D8: 1 | E8: 2650 | F8: =E8*D8 -> 2650 | H8: 1 | I8: CT | J8: Ningbo ZENTEC Air Conditioning & Refrigeration Co., Ltd | K8: Китай | L8: отсутствует | M8: отсутствует | N8: шт
B9: 8481309908 | D9: 1 | E9: 2340 | F9: =E9*D9 -> 2340 | H9: 1 | I9: CT | J9: Ningbo ZENTEC Air Conditioning & Refrigeration Co., Ltd | K9: Китай | L9: отсутствует | M9: отсутствует | N9: шт
B10: 8481309908 | D10: 1 | E10: 2340 | F10: =E10*D10 -> 2340 | H10: 1 | I10: CT | J10: Ningbo ZENTEC Air Conditioning & Refrigeration Co., Ltd | K10: Китай | L10: отсутствует | M10: отсутствует | N10: шт
B11: 8481309908 | D11: 1 | E11: 1980 | F11: =E11*D11 -> 1980 | H11: 1 | I11: CT | J11: Ningbo ZENTEC Air Conditioning & Refrigeration Co., Ltd | K11: Китай | L11: отсутствует | M11: отсутствует | N11: шт
B12: 8481309908 | D12: 1 | E12: 1960 | F12: =E12*D12 -> 1960 | H12: 1 | I12: CT | J12: Ningbo ZENTEC Air Conditioning & Refrigeration Co., Ltd | K12: Китай | L12: отсутствует | M12: отсутствует | N12: шт
B13: 8481309908 | D13: 1 | E13: 1850 | F13: =E13*D13 -> 1850 | H13: 1 | I13: CT | J13: Ningbo ZENTEC Air Conditioning & Refrigeration Co., Ltd | K13: Китай | L13: отсутствует | M13: отсутствует | N13: шт
B14: 8481309908 | D14: 1 | E14: 1960 | F14: =E14*D14 -> 1960 | H14: 1 | I14: CT | J14: Ningbo ZENTEC Air Conditioning & Refrigeration Co., Ltd | K14: Китай | L14: отсутствует | M14: отсутствует | N14: шт
B15: 8481309908 | C15: =VLOOKUP(A15,Лист1!$B$1:$Q$28,5,0) -> #N/A | E15: =VLOOKUP(A15,Лист1!$B$1:$Q$28,3,0) -> #N/A | F15: =E15*D15 -> #N/A | I15: CT | J15: Ningbo ZENTEC Air Conditioning & Refrigeration Co., Ltd | K15: Китай | L15: отсутствует | M15: отсутствует | N15: шт | O15: =#REF!+#REF!*0.05 -> #REF! | P15: 184
B16: 8481309908 | C16: =VLOOKUP(A16,Лист1!$B$1:$Q$28,5,0) -> #N/A | E16: =VLOOKUP(A16,Лист1!$B$1:$Q$28,3,0) -> #N/A | F16: =E16*D16 -> #N/A | I16: CT | J16: Ningbo ZENTEC Air Conditioning & Refrigeration Co., Ltd | K16: Китай | L16: отсутствует | M16: отсутствует | N16: шт | O16: =#REF!+#REF!*0.05 -> #REF! | P16: 184
B17: 8481309908 | C17: =VLOOKUP(A17,Лист1!$B$1:$Q$28,5,0) -> #N/A | E17: =VLOOKUP(A17,Лист1!$B$1:$Q$28,3,0) -> #N/A | F17: =E17*D17 -> #N/A | I17: CT | J17: Ningbo ZENTEC Air Conditioning & Refrigeration Co., Ltd | K17: Китай | L17: отсутствует | M17: отсутствует | N17: шт | O17: =#REF!+#REF!*0.05 -> #REF! | P17: 184
B18: 8481309908 | C18: =VLOOKUP(A18,Лист1!$B$1:$Q$28,5,0) -> #N/A | E18: =VLOOKUP(A18,Лист1!$B$1:$Q$28,3,0) -> #N/A | F18: =E18*D18 -> #N/A | I18: CT | J18: Ningbo ZENTEC Air Conditioning & Refrigeration Co., Ltd | K18: Китай | L18: отсутствует | M18: отсутствует | N18: шт | O18: =#REF!+#REF!*0.05 -> #REF! | P18: 184
B19: 8481309908 | C19: =VLOOKUP(A19,Лист1!$B$1:$Q$28,5,0) -> #N/A | E19: =VLOOKUP(A19,Лист1!$B$1:$Q$28,3,0) -> #N/A | F19: =E19*D19 -> #N/A | I19: CT | J19: Ningbo ZENTEC Air Conditioning & Refrigeration Co., Ltd | K19: Китай | L19: отсутствует | M19: отсутствует | N19: шт | O19: =#REF!+#REF!*0.05 -> #REF! | P19: 184
B20: 8481309908 | C20: =VLOOKUP(A20,Лист1!$B$1:$Q$28,5,0) -> #N/A | E20: =VLOOKUP(A20,Лист1!$B$1:$Q$28,3,0) -> #N/A | F20: =E20*D20 -> #N/A | I20: CT | J20: Ningbo ZENTEC Air Conditioning & Refrigeration Co., Ltd | K20: Китай | L20: отсутствует | M20: отсутствует | N20: шт | O20: =#REF!+#REF!*0.05 -> #REF! | P20: 184
B21: 8481309908 | C21: =VLOOKUP(A21,Лист1!$B$1:$Q$28,5,0) -> #N/A | E21: =VLOOKUP(A21,Лист1!$B$1:$Q$28,3,0) -> #N/A | F21: =E21*D21 -> #N/A | I21: CT | J21: Ningbo ZENTEC Air Conditioning & Refrigeration Co., Ltd | K21: Китай | L21: отсутствует | M21: отсутствует | N21: шт | O21: =#REF!+#REF!*0.05 -> #REF! | P21: 184
B22: 8481309908 | C22: =VLOOKUP(A22,Лист1!$B$1:$Q$28,5,0) -> #N/A | E22: =VLOOKUP(A22,Лист1!$B$1:$Q$28,3,0) -> #N/A | F22: =E22*D22 -> #N/A | I22: CT | J22: Ningbo ZENTEC Air Conditioning & Refrigeration Co., Ltd | K22: Китай | L22: отсутствует | M22: отсутствует | N22: шт | O22: =#REF!+#REF!*0.05 -> #REF! | P22: 184
B23: 8481309908 | C23: =VLOOKUP(A23,Лист1!$B$1:$Q$28,5,0) -> #N/A | E23: =VLOOKUP(A23,Лист1!$B$1:$Q$28,3,0) -> #N/A | F23: =E23*D23 -> #N/A | I23: CT | J23: Ningbo ZENTEC Air Conditioning & Refrigeration Co., Ltd | K23: Китай | L23: отсутствует | M23: отсутствует | N23: шт | O23: =#REF!+#REF!*0.05 -> #REF! | P23: 184
B24: 8481309908 | C24: =VLOOKUP(A24,Лист1!$B$1:$Q$28,5,0) -> #N/A | E24: =VLOOKUP(A24,Лист1!$B$1:$Q$28,3,0) -> #N/A | F24: =E24*D24 -> #N/A | I24: CT | J24: SHANGHAI JINGPUMECHANICAL & ELECTRICAL TECHNOLOGY CO.,LTD. | K24: Китай | L24: отсутствует | M24: отсутствует | N24: шт | O24: =#REF!+#REF!*0.05 -> #REF! | P24: 184
B25: 8481309908 | C25: =VLOOKUP(A25,Лист1!$B$1:$Q$28,5,0) -> #N/A | E25: =VLOOKUP(A25,Лист1!$B$1:$Q$28,3,0) -> #N/A | F25: =E25*D25 -> #N/A | I25: CT | J25: SHANGHAI JINGPUMECHANICAL & ELECTRICAL TECHNOLOGY CO.,LTD. | K25: Китай | L25: отсутствует | M25: отсутствует | N25: шт | O25: =#REF!+#REF!*0.05 -> #REF! | P25: 184
B26: 8481309908 | C26: =VLOOKUP(A26,Лист1!$B$1:$Q$28,5,0) -> #N/A | E26: =VLOOKUP(A26,Лист1!$B$1:$Q$28,3,0) -> #N/A | F26: =E26*D26 -> #N/A | I26: CT | J26: SHANGHAI JINGPUMECHANICAL & ELECTRICAL TECHNOLOGY CO.,LTD. | K26: Китай | L26: отсутствует | M26: отсутствует | N26: шт | O26: =#REF!+#REF!*0.05 -> #REF! | P26: 184
... B40: 8481309908 | C40: =VLOOKUP(A40,Лист1!$B$1:$Q$28,5,0) -> #N/A | E40: =VLOOKUP(A40,Лист1!$B$1:$Q$28,3,0) -> #N/A | F40: =E40*D40 -> #N/A | I40: CT | J40: SHANGHAI JINGPUMECHANICAL & ELECTRICAL TECHNOLOGY CO.,LTD. | K40: Китай | L40: отсутствует | M40: отсутствует | N40: шт | O40: =#REF!+#REF!*0.05 -> #REF! | P40: 184
B41: 8481309908 | C41: =VLOOKUP(A41,Лист1!$B$1:$Q$28,5,0) -> #N/A | E41: =VLOOKUP(A41,Лист1!$B$1:$Q$28,3,0) -> #N/A | F41: =E41*D41 -> #N/A | G41: =VLOOKUP(A41,Лист1!$B$1:$Q$28,4,0) -> #N/A | I41: CT | J41: SHANGHAI JINGPUMECHANICAL & ELECTRICAL TECHNOLOGY CO.,LTD. | K41: Китай | L41: отсутствует | M41: отсутствует | N41: шт | O41: =#REF!+#REF!*0.05 -> #REF! | P41: 184
B42: 8481309908 | C42: =VLOOKUP(A42,Лист1!$B$1:$Q$28,5,0) -> #N/A | E42: =VLOOKUP(A42,Лист1!$B$1:$Q$28,3,0) -> #N/A | F42: =E42*D42 -> #N/A | G42: =VLOOKUP(A42,Лист1!$B$1:$Q$28,4,0) -> #N/A | I42: CT | J42: SHANGHAI JINGPUMECHANICAL & ELECTRICAL TECHNOLOGY CO.,LTD. | K42: Китай | L42: отсутствует | M42: отсутствует | N42: шт | O42: =#REF!+#REF!*0.05 -> #REF! | P42: 184
B43: 8481309908 | C43: =VLOOKUP(A43,Лист1!$B$1:$Q$28,5,0) -> #N/A | E43: =VLOOKUP(A43,Лист1!$B$1:$Q$28,3,0) -> #N/A | F43: =E43*D43 -> #N/A | G43: =VLOOKUP(A43,Лист1!$B$1:$Q$28,4,0) -> #N/A | I43: CT | J43: SHANGHAI JINGPUMECHANICAL & ELECTRICAL TECHNOLOGY CO.,LTD. | K43: Китай | L43: отсутствует | M43: отсутствует | N43: шт | O43: =#REF!+#REF!*0.05 -> #REF! | P43: 184
B44: 8481309908 | C44: =VLOOKUP(A44,Лист1!$B$1:$Q$28,5,0) -> #N/A | E44: =VLOOKUP(A44,Лист1!$B$1:$Q$28,3,0) -> #N/A | F44: =E44*D44 -> #N/A | G44: =VLOOKUP(A44,Лист1!$B$1:$Q$28,4,0) -> #N/A | I44: CT | J44: SHANGHAI JINGPUMECHANICAL & ELECTRICAL TECHNOLOGY CO.,LTD. | K44: Китай | L44: отсутствует | M44: отсутствует | N44: шт | O44: =#REF!+#REF!*0.05 -> #REF! | P44: 184
B45: 8481309908 | C45: =VLOOKUP(A45,Лист1!$B$1:$Q$28,5,0) -> #N/A | E45: =VLOOKUP(A45,Лист1!$B$1:$Q$28,3,0) -> #N/A | F45: =E45*D45 -> #N/A | G45: =VLOOKUP(A45,Лист1!$B$1:$Q$28,4,0) -> #N/A | I45: CT | J45: SHANGHAI JINGPUMECHANICAL & ELECTRICAL TECHNOLOGY CO.,LTD. | K45: Китай | L45: отсутствует | M45: отсутствует | N45: шт | O45: =#REF!+#REF!*0.05 -> #REF! | P45: 184
B46: 8481309908 | C46: =VLOOKUP(A46,Лист1!$B$1:$Q$28,5,0) -> #N/A | E46: =VLOOKUP(A46,Лист1!$B$1:$Q$28,3,0) -> #N/A | F46: =E46*D46 -> #N/A | G46: =VLOOKUP(A46,Лист1!$B$1:$Q$28,4,0) -> #N/A | I46: CT | J46: SHANGHAI JINGPUMECHANICAL & ELECTRICAL TECHNOLOGY CO.,LTD. | K46: Китай | L46: отсутствует | M46: отсутствует | N46: шт | O46: =#REF!+#REF!*0.05 -> #REF! | P46: 184
B47: 8481309908 | C47: =VLOOKUP(A47,Лист1!$B$1:$Q$28,5,0) -> #N/A | E47: =VLOOKUP(A47,Лист1!$B$1:$Q$28,3,0) -> #N/A | F47: =E47*D47 -> #N/A | G47: =VLOOKUP(A47,Лист1!$B$1:$Q$28,4,0) -> #N/A | I47: CT | J47: SHANGHAI JINGPUMECHANICAL & ELECTRICAL TECHNOLOGY CO.,LTD. | K47: Китай | L47: отсутствует | M47: отсутствует | N47: шт | O47: =#REF!+#REF!*0.05 -> #REF! | P47: 184
B48: 8481309908 | C48: =VLOOKUP(A48,Лист1!$B$1:$Q$28,5,0) -> #N/A | E48: =VLOOKUP(A48,Лист1!$B$1:$Q$28,3,0) -> #N/A | F48: =E48*D48 -> #N/A | G48: =VLOOKUP(A48,Лист1!$B$1:$Q$28,4,0) -> #N/A | I48: CT | J48: SHANGHAI JINGPUMECHANICAL & ELECTRICAL TECHNOLOGY CO.,LTD. | K48: Китай | L48: отсутствует | M48: отсутствует | N48: шт | O48: =#REF!+#REF!*0.05 -> #REF! | P48: 184
B49: 8481309908 | C49: =VLOOKUP(A49,Лист1!$B$1:$Q$28,5,0) -> #N/A | E49: =VLOOKUP(A49,Лист1!$B$1:$Q$28,3,0) -> #N/A | F49: =E49*D49 -> #N/A | G49: =VLOOKUP(A49,Лист1!$B$1:$Q$28,4,0) -> #N/A | I49: CT | J49: SHANGHAI JINGPUMECHANICAL & ELECTRICAL TECHNOLOGY CO.,LTD. | K49: Китай | L49: отсутствует | M49: отсутствует | N49: шт | O49: =#REF!+#REF!*0.05 -> #REF! | P49: 184
B50: 8481309908 | C50: =VLOOKUP(A50,Лист1!$B$1:$Q$28,5,0) -> #N/A | E50: =VLOOKUP(A50,Лист1!$B$1:$Q$28,3,0) -> #N/A | F50: =E50*D50 -> #N/A | G50: =VLOOKUP(A50,Лист1!$B$1:$Q$28,4,0) -> #N/A | I50: CT | J50: SHANGHAI JINGPUMECHANICAL & ELECTRICAL TECHNOLOGY CO.,LTD. | K50: Китай | L50: отсутствует | M50: отсутствует | N50: шт | O50: =#REF!+#REF!*0.05 -> #REF! | P50: 184
B51: 8481309908 | C51: =VLOOKUP(A51,Лист1!$B$1:$Q$28,5,0) -> #N/A | E51: =VLOOKUP(A51,Лист1!$B$1:$Q$28,3,0) -> #N/A | F51: =E51*D51 -> #N/A | G51: =VLOOKUP(A51,Лист1!$B$1:$Q$28,4,0) -> #N/A | I51: CT | J51: SHANGHAI JINGPUMECHANICAL & ELECTRICAL TECHNOLOGY CO.,LTD. | K51: Китай | L51: отсутствует | M51: отсутствует | N51: шт | O51: =#REF!+#REF!*0.05 -> #REF! | P51: 184
B52: 8481309908 | C52: =VLOOKUP(A52,Лист1!$B$1:$Q$28,5,0) -> #N/A | E52: =VLOOKUP(A52,Лист1!$B$1:$Q$28,3,0) -> #N/A | F52: =E52*D52 -> #N/A | G52: =VLOOKUP(A52,Лист1!$B$1:$Q$28,4,0) -> #N/A | I52: CT | J52: SHANGHAI JINGPUMECHANICAL & ELECTRICAL TECHNOLOGY CO.,LTD. | K52: Китай | L52: отсутствует | M52: отсутствует | N52: шт | O52: =#REF!+#REF!*0.05 -> #REF! | P52: 184
... B66: 8481309908 | C66: =VLOOKUP(A66,Лист1!$B$1:$Q$28,5,0) -> #N/A | E66: =VLOOKUP(A66,Лист1!$B$1:$Q$28,3,0) -> #N/A | F66: =E66*D66 -> #N/A | G66: =VLOOKUP(A66,Лист1!$B$1:$Q$28,4,0) -> #N/A | I66: CT | J66: SHANGHAI JINGPUMECHANICAL & ELECTRICAL TECHNOLOGY CO.,LTD. | K66: Китай | L66: отсутствует | M66: отсутствует | N66: шт | O66: =#REF!+#REF!*0.05 -> #REF! | P66: 184
...

Sheet Лист1
B1: Модель | C1: Код ТН ВЭД | D1: Стоимость за единицу | E1: Наименование | F1: Прочее | G1: Номер ДС | H1: дата ДС | I1: дата начала действия ДС | J1: дата окончания действия ДС | K1: Номер СС | L1: дата СС | M1: дата начала действия СС | N1: дата окончания действия СС | O1: Артикул | P1: Тов знак | Q1: Вес изделия за единицу
B2: L-42-5050 | E2: СВЕТОДИОДНАЯ ПЛАТА L-42-5050 С 42 СВЕТОДИОДАМИ. ПОСТОЯННЫЙ ТОК: 67 ВОЛЬТ - 1100 ШТ. ЦЕНА 5,85 ЕВРО/ШТ. ГАБАРИТНЫЕ РАЗМЕРЫ, ММ: 252Х120Х2 | O2: Отсутствует | P2: Отсутствует
B3: LO-28-5050 | C3: 8541401004 | D3: 3 | E3: СВЕТОДИОДНАЯ ПЛАТА LO-28-5050 С 28 СВЕТОДИОДАМИ. ПОСТОЯННЫЙ ТОК: 67 ВОЛЬТ - 3060 ШТ. ГАБАРИТНЫЕ РАЗМЕРЫ, ММ: 219Х54Х2 | F3: СВЕТОДИОДНАЯ ПЛАТА НА АЛЮМИНИЕВОЙ ОСНОВЕ СО СВЕТОДИОДАМИ, (ИСПОЛЬЗУЕТСЯ КАК КОМПЛЕКТУЮЩЕЕ ДЛЯ ИЗГОТОВЛЕНИЯ СВЕТОДИОДНОГО ОСВЕТИТЕЛЬНОГО ОБОРУДОВАНИЯ). ОБЛАСТЬ ПРИМЕНЕНИЯ ПРОМЫШЛЕННЫЕ ПОМЕЩЕНИЯ,УЛИЧНЫЕ ПЛОЩАДКИ. НЕ ЛОМ. НЕ ОТХОДЫ. НЕ ЯВЛЯЕТСЯ ГОТОВЫМ И САМОСТОЯТЕЛЬНЫМ ИЗДЕЛИЕМ. НЕ ЯВЛЯЕТСЯ ЛАМПОЙ. ТИП ПОЛУПРОВОДНИКА: P-N. ОБЩЕПРИНЯТОЕ НАИМЕНОВАНИЕ СВЕТОДИОДЫ. | O3: Отсутствует | P3: Отсутствует | Q3: 0.049
B4: LO-28-5050 RED | C4: 8541401004 | D4: 6.5 | E4: СВЕТОДИОДНАЯ ПЛАТА LO-28-5050 С 28 СВЕТОДИОДАМИ. ПОСТОЯННЫЙ ТОК: 67 ВОЛЬТ - 3060 ШТ. ГАБАРИТНЫЕ РАЗМЕРЫ, ММ: 219Х54Х2 | F4: СВЕТОДИОДНАЯ ПЛАТА НА АЛЮМИНИЕВОЙ ОСНОВЕ СО СВЕТОДИОДАМИ, (ИСПОЛЬЗУЕТСЯ КАК КОМПЛЕКТУЮЩЕЕ ДЛЯ ИЗГОТОВЛЕНИЯ СВЕТОДИОДНОГО ОСВЕТИТЕЛЬНОГО ОБОРУДОВАНИЯ). ОБЛАСТЬ ПРИМЕНЕНИЯ ПРОМЫШЛЕННЫЕ ПОМЕЩЕНИЯ,УЛИЧНЫЕ ПЛОЩАДКИ. НЕ ЛОМ. НЕ ОТХОДЫ. НЕ ЯВЛЯЕТСЯ ГОТОВЫМ И САМОСТОЯТЕЛЬНЫМ ИЗДЕЛИЕМ. НЕ ЯВЛЯЕТСЯ ЛАМПОЙ. ТИП ПОЛУПРОВОДНИКА: P-N. ОБЩЕПРИНЯТОЕ НАИМЕНОВАНИЕ СВЕТОДИОДЫ. | O4: Отсутствует | P4: Отсутствует | Q4: 0.049
B5: LO-28-5050 GREEN | C5: 8541401004 | D5: 6.5 | E5: СВЕТОДИОДНАЯ ПЛАТА LO-28-5050 С 28 СВЕТОДИОДАМИ. ПОСТОЯННЫЙ ТОК: 67 ВОЛЬТ - 3060 ШТ. ГАБАРИТНЫЕ РАЗМЕРЫ, ММ: 219Х54Х3 | F5: СВЕТОДИОДНАЯ ПЛАТА НА АЛЮМИНИЕВОЙ ОСНОВЕ СО СВЕТОДИОДАМИ, (ИСПОЛЬЗУЕТСЯ КАК КОМПЛЕКТУЮЩЕЕ ДЛЯ ИЗГОТОВЛЕНИЯ СВЕТОДИОДНОГО ОСВЕТИТЕЛЬНОГО ОБОРУДОВАНИЯ). ОБЛАСТЬ ПРИМЕНЕНИЯ ПРОМЫШЛЕННЫЕ ПОМЕЩЕНИЯ,УЛИЧНЫЕ ПЛОЩАДКИ. НЕ ЛОМ. НЕ ОТХОДЫ. НЕ ЯВЛЯЕТСЯ ГОТОВЫМ И САМОСТОЯТЕЛЬНЫМ ИЗДЕЛИЕМ. НЕ ЯВЛЯЕТСЯ ЛАМПОЙ. ТИП ПОЛУПРОВОДНИКА: P-N. ОБЩЕПРИНЯТОЕ НАИМЕНОВАНИЕ СВЕТОДИОДЫ. | O5: Отсутствует | P5: Отсутствует | Q5: 1.049
B6: LO-28-5050 BLUE | C6: 8541401004 | D6: 4.4 | E6: СВЕТОДИОДНАЯ ПЛАТА LO-28-5050 С 28 СВЕТОДИОДАМИ. ПОСТОЯННЫЙ ТОК: 67 ВОЛЬТ - 3060 ШТ. ГАБАРИТНЫЕ РАЗМЕРЫ, ММ: 219Х54Х4 | F6: СВЕТОДИОДНАЯ ПЛАТА НА АЛЮМИНИЕВОЙ ОСНОВЕ СО СВЕТОДИОДАМИ, (ИСПОЛЬЗУЕТСЯ КАК КОМПЛЕКТУЮЩЕЕ ДЛЯ ИЗГОТОВЛЕНИЯ СВЕТОДИОДНОГО ОСВЕТИТЕЛЬНОГО ОБОРУДОВАНИЯ). ОБЛАСТЬ ПРИМЕНЕНИЯ ПРОМЫШЛЕННЫЕ ПОМЕЩЕНИЯ,УЛИЧНЫЕ ПЛОЩАДКИ. НЕ ЛОМ. НЕ ОТХОДЫ. НЕ ЯВЛЯЕТСЯ ГОТОВЫМ И САМОСТОЯТЕЛЬНЫМ ИЗДЕЛИЕМ. НЕ ЯВЛЯЕТСЯ ЛАМПОЙ. ТИП ПОЛУПРОВОДНИКА: P-N. ОБЩЕПРИНЯТОЕ НАИМЕНОВАНИЕ СВЕТОДИОДЫ.
B7: LO-28-5050/2 | C7: 8541401004 | E7: СВЕТОДИОДНАЯ ПЛАТА LO-28-5050/2 С 28 СВЕТОДИОДАМИ. ПОСТОЯННЫЙ ТОК: 48 ВОЛЬТ - 31000 ШТ. ЦЕНА 4,58 ДОЛЛ.США/ШТ. ГАБАРИТНЫЕ РАЗМЕРЫ, ММ: 219Х54Х2 | F7: СВЕТОДИОДНАЯ ПЛАТА НА АЛЮМИНИЕВОЙ ОСНОВЕ СО СВЕТОДИОДАМИ, (ИСПОЛЬЗУЕТСЯ КАК КОМПЛЕКТУЮЩЕЕ ДЛЯ ИЗГОТОВЛЕНИЯ СВЕТОДИОДНОГО ОСВЕТИТЕЛЬНОГО ОБОРУДОВАНИЯ). ОБЛАСТЬ ПРИМЕНЕНИЯ ПРОМЫШЛЕННЫЕ ПОМЕЩЕНИЯ,УЛИЧНЫЕ ПЛОЩАДКИ. НЕ ЛОМ. НЕ ОТХОДЫ. НЕ ЯВЛЯЕТСЯ ГОТОВЫМ И САМОСТОЯТЕЛЬНЫМ ИЗДЕЛИЕМ. НЕ ЯВЛЯЕТСЯ ЛАМПОЙ. ТИП ПОЛУПРОВОДНИКА: P-N. ОБЩЕПРИНЯТОЕ НАИМЕНОВАНИЕ СВЕТОДИОДЫ. | O7: Отсутствует | P7: Отсутствует | Q7: 0.049
B9: L-26-2835-79 | O9: Отсутствует | P9: Отсутствует
B10: L-26-2835-80 | C10: 8541401004 | D10: 0.74 | E10: СВЕТОДИОДНАЯ ПЛАТА L-26-2835-80 С 26 СВЕТОДИОДАМИ. ПОСТОЯННЫЙ ТОК: 11 ВОЛЬТ - 600 ШТ. ЦЕНА 0,74 ЕВРО/ШТ. ГАБАРИТНЫЕ РАЗМЕРЫ, ММ: 470Х12Х1 В 1 КАРТОННОЙ КОРОБКЕ. | F10: СВЕТОДИОДНАЯ ПЛАТА НА АЛЮМИНИЕВОЙ ОСНОВЕ СО СВЕТОДИОДАМИ, (ИСПОЛЬЗУЕТСЯ КАК КОМПЛЕКТУЮЩЕЕ ДЛЯ ИЗГОТОВЛЕНИЯ СВЕТОДИОДНОГО ОСВЕТИТЕЛЬНОГО ОБОРУДОВАНИЯ). ОБЛАСТЬ ПРИМЕНЕНИЯ ПРОМЫШЛЕННЫЕ ПОМЕЩЕНИЯ,УЛИЧНЫЕ ПЛОЩАДКИ. НЕ ЛОМ. НЕ ОТХОДЫ. НЕ ЯВЛЯЕТСЯ ГОТОВЫМ И САМОСТОЯТЕЛЬНЫМ ИЗДЕЛИЕМ. НЕ ЯВЛЯЕТСЯ ЛАМПОЙ. ТИП ПОЛУПРОВОДНИКА: P-N. ОБЩЕПРИНЯТОЕ НАИМЕНОВАНИЕ СВЕТОДИОДЫ. | O10: Отсутствует | P10: Отсутствует | Q10: 0.0135416
B11: BOARD, 26PCS 2835 LED, 2S13P | C11: 8541410004 | D11: 1 | E11: СВЕТОДИОДНАЯ ПЛАТА BOARD, 26PCS 2835 LED, 2S13P С 26 СВЕТОДИОДАМИ. ПОСТОЯННЫЙ ТОК: 18 ВОЛЬТ. ТЕМПЕРАТУРА СВЕЧЕНИЯ: 4000K - 6640 ШТ. ЦЕНА 0,89 ДОЛЛ.США/ШТ. ГАБАРИТНЫЕ РАЗМЕРЫ, ММ: 470Х14Х1. В 6 КАРТОННЫХ КОРОБКАХ. | F11: СВЕТОДИОДНАЯ ПЛАТА НА АЛЮМИНИЕВОЙ ОСНОВЕ СО СВЕТОДИОДАМИ, (ИСПОЛЬЗУЕТСЯ КАК КОМПЛЕКТУЮЩЕЕ ДЛЯ ИЗГОТОВЛЕНИЯ СВЕТОДИОДНОГО ОСВЕТИТЕЛЬНОГО ОБОРУДОВАНИЯ). ОБЛАСТЬ ПРИМЕНЕНИЯ ПРОМЫШЛЕННЫЕ ПОМЕЩЕНИЯ,УЛИЧНЫЕ ПЛОЩАДКИ. НЕ ЛОМ. НЕ ОТХОДЫ. НЕ ЯВЛЯЕТСЯ ГОТОВЫМ И САМОСТОЯТЕЛЬНЫМ ИЗДЕЛИЕМ. НЕ ЯВЛЯЕТСЯ ЛАМПОЙ. ТИП ПОЛУПРОВОДНИКА: P-N. ОБЩЕПРИНЯТОЕ НАИМЕНОВАНИЕ СВЕТОДИОДЫ. | O11: Отсутствует | P11: Отсутствует | Q11: 0.018
B12: L-26-2835-90 | C12: 8541401004 | D12: 0.84 | E12: СВЕТОДИОДНАЯ ПЛАТА L-26-2835-90 С 26 СВЕТОДИОДАМИ. ПОСТОЯННЫЙ ТОК: 11 ВОЛЬТ - 600 ШТ. ЦЕНА 0,84 ЕВРО/ШТ. ГАБАРИТНЫЕ РАЗМЕРЫ, ММ: 470Х12Х1 | F12: СВЕТОДИОДНАЯ ПЛАТА НА АЛЮМИНИЕВОЙ ОСНОВЕ СО СВЕТОДИОДАМИ, (ИСПОЛЬЗУЕТСЯ КАК КОМПЛЕКТУЮЩЕЕ ДЛЯ ИЗГОТОВЛЕНИЯ СВЕТОДИОДНОГО ОСВЕТИТЕЛЬНОГО ОБОРУДОВАНИЯ). ОБЛАСТЬ ПРИМЕНЕНИЯ ПРОМЫШЛЕННЫЕ ПОМЕЩЕНИЯ,УЛИЧНЫЕ ПЛОЩАДКИ. НЕ ЛОМ. НЕ ОТХОДЫ. НЕ ЯВЛЯЕТСЯ ГОТОВЫМ И САМОСТОЯТЕЛЬНЫМ ИЗДЕЛИЕМ. НЕ ЯВЛЯЕТСЯ ЛАМПОЙ. ТИП ПОЛУПРОВОДНИКА: P-N. ОБЩЕПРИНЯТОЕ НАИМЕНОВАНИЕ СВЕТОДИОДЫ. | O12: Отсутствует | P12: Отсутствует | Q12: 0.05
B13: LO-28-15070 | C13: 9405920008 | D13: 2.1 | E13: РАССЕИВАТЕЛЬ СВЕТА ИЗ ПОЛИКАРБОНАТА LO-28-15070. ГАБАРИТНЫЕ РАЗМЕРЫ, ММ: 219Х54Х8 | F13: ПРОЧИЕ ЧАСТИ ОСВЕТИТЕЛЬНОГО ОБОРУДОВАНИЯ, ИЗ ПЛАСТМАССЫ: РАССЕИВАТЕЛЬ СВЕТА ИЗ ПОЛИКАРБОНАТА (ИСПОЛЬЗУЕТСЯ КАК КОМПЛЕКТУЮЩЕЕ ДЛЯ ИЗГОТОВЛЕНИЯ СВЕТОДИОДНОГО ОСВЕТИТЕЛЬНОГО ОБОРУДОВАНИЯ). НОВЫЕ. | O13: Отсутствует | P13: Отсутствует | Q13: 0.08
B14: LO-28-90 | C14: 9405920008 | E14: РАССЕИВАТЕЛЬ СВЕТА ИЗ ПОЛИКАРБОНАТА LO-28-90, 336 ШТ. ЦЕНА 0,54 ЕВРО/ШТ. ГАБАРИТНЫЕ РАЗМЕРЫ, ММ: 219Х54Х8 | F14: ПРОЧИЕ ЧАСТИ ОСВЕТИТЕЛЬНОГО ОБОРУДОВАНИЯ, ИЗ ПЛАСТМАССЫ: РАССЕИВАТЕЛЬ СВЕТА ИЗ ПОЛИКАРБОНАТА (ИСПОЛЬЗУЕТСЯ КАК КОМПЛЕКТУЮЩЕЕ ДЛЯ ИЗГОТОВЛЕНИЯ СВЕТОДИОДНОГО ОСВЕТИТЕЛЬНОГО ОБОРУДОВАНИЯ). НОВЫЕ. | O14: Отсутствует | P14: Отсутствует | Q14: 0.0446
B15: LO-26-2835-90-14 | C15: 8541401004 | D15: 0.91 | E15: СВЕТОДИОДНАЯ ПЛАТА L-26-2835-90-14 С 26 СВЕТОДИОДАМИ. ПОСТОЯННЫЙ ТОК: 11 ВОЛЬТ. ГАБАРИТНЫЕ РАЗМЕРЫ, ММ: 470Х14Х1 В 13 КАРТОННЫХ КОРОБКАХ. | F15: СВЕТОДИОДНАЯ ПЛАТА НА АЛЮМИНИЕВОЙ ОСНОВЕ СО СВЕТОДИОДАМИ, (ИСПОЛЬЗУЕТСЯ КАК КОМПЛЕКТУЮЩЕЕ ДЛЯ ИЗГОТОВЛЕНИЯ СВЕТОДИОДНОГО ОСВЕТИТЕЛЬНОГО ОБОРУДОВАНИЯ). ОБЛАСТЬ ПРИМЕНЕНИЯ ПРОМЫШЛЕННЫЕ ПОМЕЩЕНИЯ, УЛИЧНЫЕ ПЛОЩАДКИ. НЕ ЛОМ. НЕ ОТХОДЫ. НЕ ЯВЛЯЕТСЯ ГОТОВЫМ И САМОСТОЯТЕЛЬНЫМ ИЗДЕЛИЕМ. НЕ ЯВЛЯЕТСЯ ЛАМПОЙ. ТИП ПОЛУПРОВОДНИКА: P-N. ОБЩЕПРИНЯТОЕ НАИМЕНОВАНИЕ СВЕТОДИОДЫ.
B16: ПРОКЛАДКА wg 28 | C16: 3926909709 | D16: 0.19 | E16: ПРОКЛАДКА. ГАБАРИТНЫЕ РАЗМЕРЫ, ММ: 170Х120Х3. В 2 КАРТОННЫХ КОРОБКАХ. | F16: ИЗДЕЛИЯ ИЗ ПЛАСТМАСС (ПОЛУЧЕННОЕ ПУТЕМ ЛИТЬЯ): ПРОКЛАДКА УПЛОТНИТЕЛЬНАЯ ИЗ СИЛИКОНА (ИСПОЛЬЗУЕТСЯ КАК КОМПЛЕКТУЮЩЕЕ ДЛЯ ИЗГОТОВЛЕНИЯ | O16: Отсутствует | P16: Отсутствует | Q16: 0.00732
B17: ВТН 0,5 | C17: 8536901000 | D17: 0.17 | E17: МОДЕЛЬ ВТН 0,5 (500 ШТ. В 1 УПАКОВКЕ). 292 УПАКОВОК. ЦЕНА 13,75 ДОЛЛ.США/УПАКОВКА. ГАБАРИТНЫЕ РАЗМЕРЫ, ММ: 3,0Х26,0. ТОЛЩИНА, ММ: 0.5. В 4 КАРТОННЫХ КОРОБКАХ. | F17: СОЕДИНИТЕЛЬ СТЫКОВОЙ ТЕРМОУСАЖИВАЕМЫЙ ИЗОЛЯЦИОННЫЙ. МАТЕРИАЛ: КОРПУС ИЗ ТЕРМОУСАДОЧНОГО МАТЕРИАЛА С МЕДНЫМ КОНТАКТОМ. НАЗНАЧЕНИЕ И ОБЛАСТЬ ПРИМЕНЕНИЯ: СОЕДИНИТЕЛЬ, ОБЕСПЕЧИВАЕТ СНЯТИЕ НАПРЯЖЕНИЯ И ЗАЩИТУ ОТ ВИБРАЦИИ В ЗАЩИЩЕННЫХ УСЛОВИЯХ, ИЗОЛИРУЕТ И ЗАЩИЩАЕТ ЭЛЕКТРОННЫЕ СОЕДИНЕНИЯ. КОМПЛЕКТУЮЩИЕ ДЛЯ ПРОИЗВОДСТВА СВЕТОДИОДНОГО ОСВЕТИТЕЛЬНОГО ОБОРУДОВАНИЯ. НЕ ЛОМ ЭЛЕКТРООБОРУДОВАНИЯ. РАССЧИТАН НА НАПРЯЖЕНИЕ 12 В. | O17: Отсутствует | P17: Отсутствует | Q17: 4e-05
B18: ВТН 1,25 | C18: 8536901000 | D18: 0.21 | E18: МОДЕЛЬ ВТН 1,25 (500 ШТ. В 1 УПАКОВКЕ). 60 УПАКОВОК. ЦЕНА 16,50 ДОЛЛ.США/УПАКОВКА. ГАБАРИТНЫЕ РАЗМЕРЫ, ММ: 4,8Х36,5. ТОЛЩИНА, ММ: 0.8. В 2 КАРТОННЫХ КОРОБКАХ. | F18: СОЕДИНИТЕЛЬ СТЫКОВОЙ ТЕРМОУСАЖИВАЕМЫЙ ИЗОЛЯЦИОННЫЙ. МАТЕРИАЛ: КОРПУС ИЗ ТЕРМОУСАДОЧНОГО МАТЕРИАЛА С МЕДНЫМ КОНТАКТОМ. НАЗНАЧЕНИЕ И ОБЛАСТЬ ПРИМЕНЕНИЯ: СОЕДИНИТЕЛЬ, ОБЕСПЕЧИВАЕТ СНЯТИЕ НАПРЯЖЕНИЯ И ЗАЩИТУ ОТ ВИБРАЦИИ В ЗАЩИЩЕННЫХ УСЛОВИЯХ, ИЗОЛИРУЕТ И ЗАЩИЩАЕТ ЭЛЕКТРОННЫЕ СОЕДИНЕНИЯ. КОМПЛЕКТУЮЩИЕ ДЛЯ ПРОИЗВОДСТВА СВЕТОДИОДНОГО ОСВЕТИТЕЛЬНОГО ОБОРУДОВАНИЯ. НЕ ЛОМ ЭЛЕКТРООБОРУДОВАНИЯ. РАССЧИТАН НА НАПРЯЖЕНИЕ 12 В. | O18: Отсутствует | P18: Отсутствует | Q18: 0.02
B19: M1 | C19: 9405990008 | E19: КОРПУС «ШУБОКС»: С ОДНИМ МОДУЛЕМ. 26 ШТ. ЦЕНА 33,05 ДОЛЛ.США/ШТ. ГАБАРИТНЫЕ РАЗМЕРЫ, ММ: 481Х312Х84. В 26 КАРТОННЫХ КОРОБКАХ. | F19: 1-ЧАСТЬ СВЕТОДИОДНОГО ОСВЕТИТЕЛЬНОГО ОБОРУДОВАНИЯ: КОРПУС ИЗ АЛЮМИНИЯ. ОБЛАСТЬ ПРИМЕНЕНИЯ – ПРОМЫШЛЕННЫЕ ПОМЕЩЕНИЯ, УЛИЧНЫЕ ПЛОШАДКИ. НЕ ДЛЯ ИСПОЛЬЗОВАНИЯ В ТРАНСПОРТНЫХ СРЕДСТВАХ, НЕ ДЛЯ МЕДИЦИНСКОГО ИСПОЛЬЗОВАНИЯ. | O19: Отсутствует | P19: Отсутствует
B20: M2 | C20: 9405990008 | E20: КОРПУС «ШУБОКС»: С ДВУМЯ МОДУЛЯМИ. 12 ШТ. ЦЕНА 43,368 ДОЛЛ.США/ШТ. ГАБАРИТНЫЕ РАЗМЕРЫ, ММ: 651Х312Х84. В 12 КАРТОННЫХ КОРОБКАХ. | F20: 1-ЧАСТЬ СВЕТОДИОДНОГО ОСВЕТИТЕЛЬНОГО ОБОРУДОВАНИЯ: КОРПУС ИЗ АЛЮМИНИЯ. ОБЛАСТЬ ПРИМЕНЕНИЯ – ПРОМЫШЛЕННЫЕ ПОМЕЩЕНИЯ, УЛИЧНЫЕ ПЛОШАДКИ. НЕ ДЛЯ ИСПОЛЬЗОВАНИЯ В ТРАНСПОРТНЫХ СРЕДСТВАХ, НЕ ДЛЯ МЕДИЦИНСКОГО ИСПОЛЬЗОВАНИЯ. | O20: Отсутствует | P20: Отсутствует
B21: М3 | C21: 7318141000 | D21: 0.004 | E21: ВИНТЫ САМОНАРЕЗАЮЩИЕ ИЗ КОРРОЗИОННОСТОЙКОЙ СТАЛИ С ЦИНКОВЫМ ПОКРЫТИЕМ, СНАБЖЕННЫЕ РЕЗЬБОЙ, 100000 ШТ. ЦЕНА 0,004 ДОЛЛ.США/ШТ В 2 КАРТОННЫХ КОРОБКАХ. | F21: ВИНТ DIN 7500 С TORX РЕЗЬБОВЫДАВЛИВАЮЩИЙ. ГОЛОВКА С ШЕСТИГРАННЫМ ШЛИЦЕМ. ВИНТ ИЗГОТОВЛЕН ИЗ НЕРЖАВЕЮЩЕЙ СТАЛИ С ОЦИНКОВКОЙ. ПРЕДЕЛ ПРОЧНОСТИ НА РАСТЯЖЕНИЕ 590 МПА. ВИД ГОЛОВКИ-ЦИЛИНДРИЧЕСКАЯ С УГЛУБЛЕНИЕМ ПОД КЛЮЧ. ОБЛАСТЬ ПРИМЕНЕНИЯ – ИСПОЛЬЗУЕТСЯ КАК КОМПЛЕКТУЮЩЕЕ ДЛЯ ПРОИЗВОДСТВА СВЕТОДИОДНОГО ОСВЕТИТЕЛЬНОГО ОБОРУДОВАНИЯ. С ПЛОСКИМ КОНЦОМ. ТОЛЩИНА СТЕРЖНЯ 2.75 ММ. | O21: Отсутствует | P21: Отсутствует | Q21: 0.0008

Sheet Лист2
