Workbook

Sheet Sheet1
B1: КОД ТН ВЭД | C1: Модель | D1: Прочее | E1: количество | F1: цена за шт | G1: стоимость | H1: наименование | I1: код упаковки грузового места | J1: производитель | K1: старна происхождения | L1: Марка | M1: тов знак | N1: ед. измерения | O1: название нотификации | P1: код документа | Q1: номер нотификации | R1: дата нотификации | S1: дата начала действия нотификации | T1: дата конца действия нотификации | U1: вес чистый за единицу | V1: вес чистый за общиий по тех описанию | W1: общий вес нетто по упаковочному | X1: БРУТТО общий | Y1: Название документа | Z1: код документа | AA1: номер Декларации соответствия | AB1: дата Декларации соответствия | AC1: дата начала действия Декларации соответствия | AD1: дата конца действия Декларации соответствия | AE1: артикул | AF1: ДТ | AG1: Компания декларант | AH1: тех описание
B2: =VLOOKUP(C2,Лист1!$B$1:$N$33,2,0) -> 8517620003 | C2: SICOM3016-2S16T-SC40-L3-L3-S | D2: =VLOOKUP(C2,Лист1!$B$2:$T$45,14,0) -> ПРОМЫШЛЕННЫЕ КОММУТАТОРЫ ДЛЯ УПРАВЛЕНИЯ В СЕТЯХ ETHERNET, НЕ ЛОМ ЭЛЕКТРООБОРУДОВАНИЯ, НЕ ПРЕДНАЗНАЧЕНЫ ДЛЯ НЕГЛАСНОГО ПОЛУЧЕНИЯ ИНФОРМАЦИИ, КОМПЛЕКТУЮЩИЕ ДЛЯ СЕРВЕРОВ И СЕРВЕРНОГО ОБОРУДОВАНИЯ, ГРАЖДАНСКОГО ПРИМЕНЕНИЯ. ПОСТАВЛЯЮТСЯ С ПЛАСТИКОВЫМИ ЗАГЛУШКАМИ ДЛЯ ПОРТОВ, МЕТАЛЛИЧЕСКИМИ УГОЛКАМИ И ПЛАСТИНАМИ ДЛЯ КРЕПЛЕНИЯ | E2: 29 | F2: 60 | G2: =E2*F2 -> 1740 | H2: SICOM3016 - промышленные коммутаторы с пониженным потреблением питания, которые могут применяться в ветроэнергетике, распределительных сетях, подстанциях, энергетических SCADA-системах, системах водоочистки, на автомагистралях, в металлургии и других сферах.Напряжение питания 24DC (18-36VDC), Потребляемая мощность менее 9.7 Вт | I2: CT | J2: Kyland Technology Co., Ltd. | K2: 156 | L2: отсутствует | M2: KYLAND | N2: шт | O2: Нотификация | P2: 10052 | Q2: RU0000033119 | R2: 42972 | S2: 42972 | T2: 44369 | W2: =#REF!*E2 -> #REF! | X2: 47.4 | Z2: 01191 | AE2: отсутствует | AF2: 10005030/030520/0123310 | AG2: Симанитрон
B3: =VLOOKUP(C3,Лист1!$B$1:$N$33,2,0) -> 8517620003 | C3: SICOM3028GPT-L3G-MB-HV-HV-S | D3: =VLOOKUP(C3,Лист1!$B$2:$T$45,14,0) -> ПРОМЫШЛЕННЫЕ КОММУТАТОРЫ ДЛЯ УПРАВЛЕНИЯ В СЕТЯХ ETHERNET, НЕ ЛОМ ЭЛЕКТРООБОРУДОВАНИЯ, НЕ ПРЕДНАЗНАЧЕНЫ ДЛЯ НЕГЛАСНОГО ПОЛУЧЕНИЯ ИНФОРМАЦИИ, КОМПЛЕКТУЮЩИЕ ДЛЯ СЕРВЕРОВ И СЕРВЕРНОГО ОБОРУДОВАНИЯ, ГРАЖДАНСКОГО ПРИМЕНЕНИЯ. ПОСТАВЛЯЮТСЯ С клеммными колодками , уголками для крепления в стойку и консольным кабелем. | E3: 2 | F3: 1716.9 | G3: =E3*F3 -> 3433.8 | H3: SICOM3028GPT-L3G-MB-HV-HV - промышленные коммутаторы с широким спектром сфер применения и модульным дизайном для простоты масштабирования и расширения функционала устройства. SICOM3028GPT-L3G могут иметь до 28 гигабитных портов. При этом возможна практически любая комбинация медных и оптических портов. Напряжение питания: 220VAC/DC (85-264VAC/77-370VDC) | I3: CT | J3: Kyland Technology Co., Ltd. | K3: 156 | L3: отсутствует | M3: KYLAND | N3: шт | O3: Нотификация | P3: 10052 | Q3: RU0000033122 | R3: 42972 | S3: 42972 | T3: 44369 | W3: =#REF!*E3 -> #REF! | X3: =W3+W3*0.094 -> #REF! | Y3: Декларации соответствия | Z3: 01191 | AA3: ЕАЭС N RU Д-CN.КА01.В.23216/20 | AB3: 43908 | AC3: 43908 | AD3: 45733 | AE3: отсутствует | AF3: 10005030/030520/0123319 | AG3: Симанитрон
B4: =VLOOKUP(C4,Лист1!$B$1:$N$33,2,0) -> 8517620003 | C4: SM6.6-2GX2GE-1U-S | D4: =VLOOKUP(C4,Лист1!$B$2:$T$45,14,0) -> ПРОМЫШЛЕННЫЕ КОММУТАТОРЫ ДЛЯ УПРАВЛЕНИЯ В СЕТЯХ ETHERNET, НЕ ЛОМ ЭЛЕКТРООБОРУДОВАНИЯ, НЕ ПРЕДНАЗНАЧЕНЫ ДЛЯ НЕГЛАСНОГО ПОЛУЧЕНИЯ ИНФОРМАЦИИ, КОМПЛЕКТУЮЩИЕ ДЛЯ СЕРВЕРОВ И СЕРВЕРНОГО ОБОРУДОВАНИЯ, ГРАЖДАНСКОГО ПРИМЕНЕНИЯ. ПОСТАВЛЯЮТСЯ С клеммными колодками , уголками для крепления в стойку и консольным кабелем. | E4: 2 | F4: 198.4 | G4: =E4*F4 -> 396.8 | H4: Описание Интерфейсный Ethernet модуль – специально разработан для коммутаторов серии SICOM3028GPT и имеет в своем составе различные типы интерфейсов в зависимости от модели. Предназначен для подключения к коммутатору других устройств, например, других коммутаторов, посредством кабелей. Модуль SM6.6-2GX2GE-1U имеет в своем составе 2 порта 10/100/1000Base-T(X) RJ45 и 2 порта 1000Base-X SFP. Энергопотребление: 3W Корпус: Металл, без вентиляторов Класс защиты: IP40 Габариты (ШxВxГ): 1U: 50.8x41.1x109.2мм Вес: 0.3 кг | I4: CT | J4: Kyland Technology Co., Ltd. | K4: 156 | L4: отсутствует | M4: KYLAND | N4: шт | O4: Нотификация | P4: 10052 | Q4: RU0000032872 | R4: 42958 | S4: 42958 | T4: 44369 | W4: =#REF!*E4 -> #REF! | X4: =W4+W4*0.094 -> #REF! | Y4: Декларации соответствия | Z4: 01191 | AE4: отсутствует | AF4: 10005030/030520/0123319 | AG4: Симанитрон
B5: =VLOOKUP(C5,Лист1!$B$1:$N$33,2,0) -> 8517620003 | C5: SM6.6-4GX-0.5U-S | D5: =VLOOKUP(C5,Лист1!$B$2:$T$45,14,0) -> ПРОМЫШЛЕННЫЕ КОММУТАТОРЫ ДЛЯ УПРАВЛЕНИЯ В СЕТЯХ ETHERNET, НЕ ЛОМ ЭЛЕКТРООБОРУДОВАНИЯ, НЕ ПРЕДНАЗНАЧЕНЫ ДЛЯ НЕГЛАСНОГО ПОЛУЧЕНИЯ ИНФОРМАЦИИ, КОМПЛЕКТУЮЩИЕ ДЛЯ СЕРВЕРОВ И СЕРВЕРНОГО ОБОРУДОВАНИЯ, ГРАЖДАНСКОГО ПРИМЕНЕНИЯ. ПОСТАВЛЯЮТСЯ С клеммными колодками , уголками для крепления в стойку и консольным кабелем. | E5: 2 | F5: 198.4 | G5: =E5*F5 -> 396.8 | H5: Описание Интерфейсный Ethernet модуль – специально разработан для коммутаторов серии SICOM3028GPT и имеет в своем составе различные типы интерфейсов в зависимости от модели. Предназначен для подключения к коммутатору других устройств, например, других коммутаторов, посредством кабелей. Модуль SM6.6-4GX-0.5U имеет в своем составе 4x1000Base-X, 100Base-FX SFP порта. Характеристики Энергопотребление: 3W Корпус: Металл, без вентиляторов Класс защиты: IP40 Габариты (ШxВxГ): 0.5U: 122.6x20.25x106.6мм Вес: 0.3 кг | I5: CT | J5: Kyland Technology Co., Ltd. | K5: 156 | L5: отсутствует | M5: KYLAND | N5: шт | O5: Нотификация | P5: 10052 | Q5: RU0000032872 | R5: 42958 | S5: 42958 | T5: 44369 | W5: =#REF!*E5 -> #REF! | X5: =W5+W5*0.094 -> #REF! | Y5: Декларации соответствия | Z5: 01191 | AE5: отсутствует | AF5: 10005030/030520/0123319 | AG5: Симанитрон
B6: =VLOOKUP(C6,Лист1!$B$1:$N$33,2,0) -> 8517620003 | C6: SM6.6-4GE-0.5U-S | D6: =VLOOKUP(C6,Лист1!$B$2:$T$45,14,0) -> ПРОМЫШЛЕННЫЕ КОММУТАТОРЫ ДЛЯ УПРАВЛЕНИЯ В СЕТЯХ ETHERNET, НЕ ЛОМ ЭЛЕКТРООБОРУДОВАНИЯ, НЕ ПРЕДНАЗНАЧЕНЫ ДЛЯ НЕГЛАСНОГО ПОЛУЧЕНИЯ ИНФОРМАЦИИ, КОМПЛЕКТУЮЩИЕ ДЛЯ СЕРВЕРОВ И СЕРВЕРНОГО ОБОРУДОВАНИЯ, ГРАЖДАНСКОГО ПРИМЕНЕНИЯ. ПОСТАВЛЯЮТСЯ С клеммными колодками , уголками для крепления в стойку и консольным кабелем. | E6: 10 | F6: 198.4 | G6: =E6*F6 -> 1984 | H6: Описание Интерфейсный Ethernet модуль – специально разработан для коммутаторов серии SICOM3028GPT и имеет в своем составе различные типы интерфейсов в зависимости от модели. Предназначен для подключения к коммутатору других устройств, например, других коммутаторов, посредством кабелей. Модуль SM6.6-4GE-0.5U имеет в своем составе 4 порта 10/100/1000Base-T(X) RJ45 Характеристики Энергопотребление: 3W Корпус: Металл, без вентиляторов Класс защиты: IP40 Габариты (ШxВxГ): 0.5U: 122.6x20.25x106.6мм Вес: 0.3 к | I6: CT | J6: Kyland Technology Co., Ltd. | K6: 156 | L6: отсутствует | M6: KYLAND | N6: шт | O6: Нотификация | P6: 10052 | Q6: RU0000032872 | R6: 42958 | S6: 42958 | T6: 44369 | W6: =#REF!*E6 -> #REF! | X6: =W6+W6*0.094 -> #REF! | Y6: Декларации соответствия | Z6: 01191 | AE6: отсутствует | AF6: 10005030/030520/0123319 | AG6: Симанитрон
B7: =VLOOKUP(C7,Лист1!$B$1:$N$33,2,0) -> 8517620003 | C7: SICOM3024P-4GX24T-HV-HV-S | D7: =VLOOKUP(C7,Лист1!$B$2:$T$45,14,0) -> ПРОМЫШЛЕННЫЕ КОММУТАТОРЫ ДЛЯ УПРАВЛЕНИЯ В СЕТЯХ ETHERNET, НЕ ЛОМ ЭЛЕКТРООБОРУДОВАНИЯ, НЕ ПРЕДНАЗНАЧЕНЫ ДЛЯ НЕГЛАСНОГО ПОЛУЧЕНИЯ ИНФОРМАЦИИ, КОМПЛЕКТУЮЩИЕ ДЛЯ СЕРВЕРОВ И СЕРВЕРНОГО ОБОРУДОВАНИЯ, ГРАЖДАНСКОГО ПРИМЕНЕНИЯ. ПОСТАВЛЯЮТСЯ С клеммными колодками , уголками для крепления в стойку и консольным кабелем. | E7: 4 | F7: 894 | G7: =E7*F7 -> 3576 | H7: SICOM3024P - промышленные коммутаторы.Данный коммутатор предназначен для передачи Ethernet пакетов по сетям передачи данным по оптическим и медным средам передачи данных. Данным коммутатором поддерживаются протоколы шифрования SSL и HTTPS использующий асимметричную криптографию для аутентификации ключей обмена и симметричное шифрование для сохранения конфиденциальности. Данный коммутатор поддерживает протокол SSH для создания шифрованного тоннеля передачи данных. Данный коммутатор имеет систему защиты интерфейса настроек назначаемым паролем. Напряжение питания Резервированное: 220VAC/DCW (85-264 Вольт переменного тока/77-30018-36 Вольт постоянного тока) | I7: CT | J7: Kyland Technology Co., Ltd. | K7: 156 | L7: отсутствует | M7: KYLAND | N7: шт | O7: Нотификация | P7: 10052 | Q7: RU0000033121 | R7: 42972 | S7: 42972 | T7: 44370 | W7: =#REF!*E7 -> #REF! | X7: =W7+W7*0.094 -> #REF! | Y7: Декларации соответствия | Z7: 01191 | AA7: ЕАЭС N RU Д-CN.КА01.В.17403/19 | AB7: 43787 | AC7: 43787 | AD7: 45613 | AE7: отсутствует | AF7: 10005030/030620/0150971 | AG7: Симанитрон
A8: 43998 | B8: =VLOOKUP(C8,Лист1!$B$1:$N$33,2,0) -> #N/A | C8: SICOM3028GPT-L2F-MB-HV-HV-S | D8: =VLOOKUP(C8,Лист1!$B$2:$T$45,14,0) -> #N/A | E8: 1 | F8: 868 | G8: =F8*E8 -> 868 | H8: SICOM3028GPT-L2F-MB-HV-HV-S - промышленные коммутаторы с широким спектром сфер применния и модульным дизайном для простоты масштабирования и расширения функционала устройства. Напряжение питания Резервированное: 220VAC/VDC (77-300VDC/85-264VAC) | I8: CT | J8: Kyland Technology Co., Ltd. | K8: 156 | L8: отсутствует | M8: KYLAND | N8: шт | O8: Нотификация | P8: 10052 | Q8: RU0000033122 | R8: 42972 | S8: 42972 | T8: 44369 | W8: =#REF!*E8 -> #REF! | X8: 8.95 | Y8: Декларации соответствия | Z8: 01191 | AA8: ЕАЭС N RU Д-CN.КА01.В.23216/20 | AB8: 43908 | AC8: 43908 | AD8: 45733 | AE8: отсутствует | AF8: 10005030/260620/0173975 | AG8: Симанитрон
A9: 43998 | B9: =VLOOKUP(C9,Лист1!$B$1:$N$33,2,0) -> 8517620003 | C9: SM6.6-4GE-1U-S | D9: =VLOOKUP(C9,Лист1!$B$2:$T$45,14,0) -> ПРОМЫШЛЕННЫЕ КОММУТАТОРЫ ДЛЯ УПРАВЛЕНИЯ В СЕТЯХ ETHERNET, НЕ ЛОМ ЭЛЕКТРООБОРУДОВАНИЯ, НЕ ПРЕДНАЗНАЧЕНЫ ДЛЯ НЕГЛАСНОГО ПОЛУЧЕНИЯ ИНФОРМАЦИИ, КОМПЛЕКТУЮЩИЕ ДЛЯ СЕРВЕРОВ И СЕРВЕРНОГО ОБОРУДОВАНИЯ, ГРАЖДАНСКОГО ПРИМЕНЕНИЯ. ПОСТАВЛЯЮТСЯ С клеммными колодками , уголками для крепления в стойку и консольным кабелем. | E9: 1 | F9: 198 | G9: =F9*E9 -> 198 | H9: Описание Интерфейсный Ethernet модуль – специально разработан для коммутаторов серии SICOM3028GPT и имеет в своем составе различные типы интерфейсов в зависимости от модели. Предназначен для подключения к коммутатору других устройств, например, других коммутаторов, посредством кабелей. Модуль SM6.6-4GE-1U-S имеет в своем составе 4 порта 10/100/1000Base-T(X) RJ45. Характеристики Энергопотребление: 3W Корпус: Металл, без вентиляторов Класс защиты: IP40 Габариты (ШxВxГ): 1U: 50.8x41.1x109.2мм Вес: 0.3 кг | I9: CT | J9: Kyland Technology Co., Ltd. | K9: 156 | L9: отсутствует | M9: KYLAND | N9: шт | O9: Нотификация | P9: 10052 | Q9: RU0000032872 | R9: 42958 | S9: 42958 | T9: 44369 | W9: =#REF!*E9 -> #REF! | X9: 0.35 | Y9: Декларации соответствия | Z9: 01191 | AE9: отсутствует | AF9: 10005030/260620/0173975 | AG9: Симанитрон
A10: 43998 | B10: =VLOOKUP(C10,Лист1!$B$1:$N$33,2,0) -> 8517620003 | C10: SM6.6-4M-ST05-0.5U-S | D10: =VLOOKUP(C10,Лист1!$B$2:$T$45,14,0) -> ПРОМЫШЛЕННЫЕ КОММУТАТОРЫ ДЛЯ УПРАВЛЕНИЯ В СЕТЯХ ETHERNET, НЕ ЛОМ ЭЛЕКТРООБОРУДОВАНИЯ, НЕ ПРЕДНАЗНАЧЕНЫ ДЛЯ НЕГЛАСНОГО ПОЛУЧЕНИЯ ИНФОРМАЦИИ, КОМПЛЕКТУЮЩИЕ ДЛЯ СЕРВЕРОВ И СЕРВЕРНОГО ОБОРУДОВАНИЯ, ГРАЖДАНСКОГО ПРИМЕНЕНИЯ. ПОСТАВЛЯЮТСЯ С клеммными колодками , уголками для крепления в стойку и консольным кабелем. | E10: 2 | F10: 264 | G10: =F10*E10 -> 528 | H10: Описание Интерфейсный Ethernet модуль – специально разработан для коммутаторов серии SICOM3028GPT и имеет в своем составе различные типы интерфейсов в зависимости от модели. Предназначен для подключения к коммутатору других устройств, например, других коммутаторов, посредством кабелей. Модуль SM6.6-4M-ST05-0.5U-S имеет в своем составе 4x100Base-FX оптических порта, многомод., коннектор SТ, 5км. Характеристики Энергопотребление: 3W Корпус: Металл, без вентиляторов Класс защиты: IP40 Габариты (ШxВxГ): 0.5U: 122.6x20.25x106.6мм Вес: 0.3 кг | I10: CT | J10: Kyland Technology Co., Ltd. | K10: 156 | L10: отсутствует | M10: KYLAND | N10: шт | O10: Нотификация | P10: 10052 | Q10: RU0000032872 | R10: 42958 | S10: 42958 | T10: 44369 | W10: =#REF!*E10 -> #REF! | X10: 0.7 | Y10: Декларации соответствия | Z10: 01191 | AE10: отсутствует | AF10: 10005030/260620/0173975 | AG10: Симанитрон
A11: 43998 | B11: =VLOOKUP(C11,Лист1!$B$1:$N$33,2,0) -> 8517620003 | C11: SICOM3000-8T-HV-S | D11: =VLOOKUP(C11,Лист1!$B$2:$T$45,14,0) -> ПРОМЫШЛЕННЫЕ КОММУТАТОРЫ ДЛЯ УПРАВЛЕНИЯ В СЕТЯХ ETHERNET, НЕ ЛОМ ЭЛЕКТРООБОРУДОВАНИЯ, НЕ ПРЕДНАЗНАЧЕНЫ ДЛЯ НЕГЛАСНОГО ПОЛУЧЕНИЯ ИНФОРМАЦИИ, КОМПЛЕКТУЮЩИЕ ДЛЯ СЕРВЕРОВ И СЕРВЕРНОГО ОБОРУДОВАНИЯ, ГРАЖДАНСКОГО ПРИМЕНЕНИЯ. ПОСТАВЛЯЮТСЯ С клеммными колодками , уголками для крепления в стойку и консольным кабелем. | E11: 11 | F11: 229.5 | G11: =F11*E11 -> 2524.5 | H11: SICOM3000-8T-HV-S - промышленные коммутаторы с пониженным потреблением питания, которые могут применяться в ветроэнергетике, распределительных сетях, подстанциях, энергетических SCADA-системах, системах водоочистки, на автомагистралях, в металлургии и других сферах. Напряжение питания 220AC/DC(132-300VAC/176-400VDC) | I11: CT | J11: Kyland Technology Co., Ltd. | K11: 156 | L11: отсутствует | M11: KYLAND | N11: шт | O11: Нотификация | P11: 10052 | Q11: RU0000033118 | R11: 42972 | S11: 42972 | T11: 44369 | W11: =#REF!*E11 -> #REF! | X11: 18 | Y11: Декларации соответствия | AA11: ЕАЭС N RU Д-CN.КА01.В.17403/19 | AB11: 43787 | AC11: 43787 | AD11: 45613 | AE11: отсутствует | AF11: 10005030/260620/0173975 | AG11: Симанитрон
A12: 44063 | B12: =VLOOKUP(C12,Лист1!$B$1:$N$33,2,0) -> 8517620003 | C12: SICOM3307S-3G7P-L10-L10-S | D12: =VLOOKUP(C12,Лист1!$B$2:$T$45,14,0) -> ПРОМЫШЛЕННЫЕ КОММУТАТОРЫ ДЛЯ УПРАВЛЕНИЯ В СЕТЯХ ETHERNET, НЕ ЛОМ ЭЛЕКТРООБОРУДОВАНИЯ, НЕ ПРЕДНАЗНАЧЕНЫ ДЛЯ НЕГЛАСНОГО ПОЛУЧЕНИЯ ИНФОРМАЦИИ, КОМПЛЕКТУЮЩИЕ ДЛЯ СЕРВЕРОВ И СЕРВЕРНОГО ОБОРУДОВАНИЯ, ГРАЖДАНСКОГО ПРИМЕНЕНИЯ. ПОСТАВЛЯЮТСЯ С клеммными колодками , уголками для крепления в стойку и консольным кабелем. | E12: 1 | F12: 638 | G12: =F12*E12 -> 638 | H12: =VLOOKUP(C12,Лист1!$B$1:$N$33,4,0) -> SICOM3028GPT-L3G-MB-HV-HV-S - ПРОМЫШЛЕННЫЕ КОММУТАТОРЫ С ШИРОКИМ СПЕКТРОМ СФЕР ПРИМЕНЕНИЯ И МОДУЛЬНЫМ ДИЗАЙНОМ ДЛЯ ПРОСТОТЫ МАСШТАБИРОВАНИЯ И РАСШИРЕНИЯ ФУНКЦИОНАЛА УСТРОЙСТВА. SICOM3028GPT-L3G МОГУТ ИМЕТЬ ДО 28 ГИГАБИТНЫХ ПОРТОВ. ПРИ ЭТОМ ВОЗМОЖНА ПРАКТИЧЕСКИ ЛЮБАЯ КОМБИНАЦИЯ МЕДНЫХ И ОПТИЧЕСКИХ ПОРТОВ. ПИТАНИЕ: НАПРЯЖЕНИЕ ПИТАНИЯ: 220VAC/DC (85-264VAC/77-370VDC) МЕХАНИЧЕСКИЕ ХАРАКТЕРИСТИКИ: РАЗМЕРЫ 482.6 X 44 X 360 ММ КРЕПЛЕНИЕ 19" СТОЙКА КЛАСС ЗАЩИТЫ IP40 ВЕС 10 КГ РАБОЧАЯ ТЕМПЕРАТУРА ОТ -40 ДО +85С ТЕМПЕРАТУРА ХРАНЕНИЯ -40 ДО +85C ВЛАЖНОСТЬ ОТ 5 ДО 95% (БЕЗ КОНДЕНСАТА) MTBF 368000 ЧАСОВ ГАРАНТИЯ 5 ЛЕТ | I12: CT | J12: Kyland Technology Co., Ltd. | K12: 156 | L12: отсутствует | M12: KYLAND | N12: шт | O12: Нотификация | P12: 10052 | Q12: =VLOOKUP(C12,Лист1!$B$1:$N$33,5,0) -> RU0000033119 | R12: =VLOOKUP(C12,Лист1!$B$1:$N$33,6,0) -> 42972 | S12: =VLOOKUP(C12,Лист1!$B$1:$N$33,7,0) -> 42972 | T12: =VLOOKUP(C12,Лист1!$B$1:$N$33,8,0) -> 44369 | U12: =VLOOKUP(C12,Лист1!$B$1:$N$33,9,0) -> 1.25 | V12: =U12*E12 -> 1.25 | W12: 1.8 | X12: =W12+W12*0.078 -> 1.9404 | Y12: Декларации соответствия | AE12: отсутствует | AF12: 10005030/090920/0260337 | AG12: Симанитрон
A13: 44063 | B13: =VLOOKUP(C13,Лист1!$B$1:$N$33,2,0) -> 8517620003 | C13: KPS2204-2T4D-L3-L3-S | D13: =VLOOKUP(C13,Лист1!$B$2:$T$45,14,0) -> ПРОМЫШЛЕННЫЕ КОММУТАТОРЫ ДЛЯ УПРАВЛЕНИЯ В СЕТЯХ ETHERNET, НЕ ЛОМ ЭЛЕКТРООБОРУДОВАНИЯ, НЕ ПРЕДНАЗНАЧЕНЫ ДЛЯ НЕГЛАСНОГО ПОЛУЧЕНИЯ ИНФОРМАЦИИ, КОМПЛЕКТУЮЩИЕ ДЛЯ СЕРВЕРОВ И СЕРВЕРНОГО ОБОРУДОВАНИЯ, ГРАЖДАНСКОГО ПРИМЕНЕНИЯ. ПОСТАВЛЯЮТСЯ С клеммными колодками , уголками для крепления в стойку и консольным кабелем. | E13: 1 | F13: 291 | G13: =F13*E13 -> 291 | H13: =VLOOKUP(C13,Лист1!$B$1:$N$33,4,0) -> SICOM3028GPT-L3G-MB-HV-HV-S - ПРОМЫШЛЕННЫЕ КОММУТАТОРЫ С ШИРОКИМ СПЕКТРОМ СФЕР ПРИМЕНЕНИЯ И МОДУЛЬНЫМ ДИЗАЙНОМ ДЛЯ ПРОСТОТЫ МАСШТАБИРОВАНИЯ И РАСШИРЕНИЯ ФУНКЦИОНАЛА УСТРОЙСТВА. SICOM3028GPT-L3G МОГУТ ИМЕТЬ ДО 28 ГИГАБИТНЫХ ПОРТОВ. ПРИ ЭТОМ ВОЗМОЖНА ПРАКТИЧЕСКИ ЛЮБАЯ КОМБИНАЦИЯ МЕДНЫХ И ОПТИЧЕСКИХ ПОРТОВ. ПИТАНИЕ: НАПРЯЖЕНИЕ ПИТАНИЯ: 220VAC/DC (85-264VAC/77-370VDC) МЕХАНИЧЕСКИЕ ХАРАКТЕРИСТИКИ: РАЗМЕРЫ 482.6 X 44 X 360 ММ КРЕПЛЕНИЕ 19" СТОЙКА КЛАСС ЗАЩИТЫ IP40 ВЕС 10 КГ РАБОЧАЯ ТЕМПЕРАТУРА ОТ -40 ДО +85С ТЕМПЕРАТУРА ХРАНЕНИЯ -40 ДО +85C ВЛАЖНОСТЬ ОТ 5 ДО 95% (БЕЗ КОНДЕНСАТА) MTBF 368000 ЧАСОВ ГАРАНТИЯ 5 ЛЕТ | I13: CT | J13: Kyland Technology Co., Ltd. | K13: 156 | L13: отсутствует | M13: KYLAND | N13: шт | O13: Нотификация | P13: 10052 | Q13: =VLOOKUP(C13,Лист1!$B$1:$N$33,5,0) -> RU0000033119 | R13: =VLOOKUP(C13,Лист1!$B$1:$N$33,6,0) -> 42972 | S13: =VLOOKUP(C13,Лист1!$B$1:$N$33,7,0) -> 42972 | T13: =VLOOKUP(C13,Лист1!$B$1:$N$33,8,0) -> 44369 | U13: 0.69 | V13: =U13*E13 -> 0.69 | W13: 1 | X13: =W13+W13*0.078 -> 1.078 | Y13: Декларации соответствия | AE13: отсутствует | AF13: 10005030/090920/0260337 | AG13: Симанитрон
A14: 44063 | B14: =VLOOKUP(C14,Лист1!$B$1:$N$33,2,0) -> 8517620003 | C14: SICOM3028GPT-L3G-MB-HV-HV-S | D14: =VLOOKUP(C14,Лист1!$B$2:$T$45,14,0) -> ПРОМЫШЛЕННЫЕ КОММУТАТОРЫ ДЛЯ УПРАВЛЕНИЯ В СЕТЯХ ETHERNET, НЕ ЛОМ ЭЛЕКТРООБОРУДОВАНИЯ, НЕ ПРЕДНАЗНАЧЕНЫ ДЛЯ НЕГЛАСНОГО ПОЛУЧЕНИЯ ИНФОРМАЦИИ, КОМПЛЕКТУЮЩИЕ ДЛЯ СЕРВЕРОВ И СЕРВЕРНОГО ОБОРУДОВАНИЯ, ГРАЖДАНСКОГО ПРИМЕНЕНИЯ. ПОСТАВЛЯЮТСЯ С клеммными колодками , уголками для крепления в стойку и консольным кабелем. | E14: 2 | F14: 1368 | G14: =F14*E14 -> 2736 | H14: =VLOOKUP(C14,Лист1!$B$1:$N$33,4,0) -> SICOM3028GPT-L3G-MB-HV-HV-S - ПРОМЫШЛЕННЫЕ КОММУТАТОРЫ С ШИРОКИМ СПЕКТРОМ СФЕР ПРИМЕНЕНИЯ И МОДУЛЬНЫМ ДИЗАЙНОМ ДЛЯ ПРОСТОТЫ МАСШТАБИРОВАНИЯ И РАСШИРЕНИЯ ФУНКЦИОНАЛА УСТРОЙСТВА. SICOM3028GPT-L3G МОГУТ ИМЕТЬ ДО 28 ГИГАБИТНЫХ ПОРТОВ. ПРИ ЭТОМ ВОЗМОЖНА ПРАКТИЧЕСКИ ЛЮБАЯ КОМБИНАЦИЯ МЕДНЫХ И ОПТИЧЕСКИХ ПОРТОВ. ПИТАНИЕ: НАПРЯЖЕНИЕ ПИТАНИЯ: 220VAC/DC (85-264VAC/77-370VDC) МЕХАНИЧЕСКИЕ ХАРАКТЕРИСТИКИ: РАЗМЕРЫ 482.6 X 44 X 360 ММ КРЕПЛЕНИЕ 19" СТОЙКА КЛАСС ЗАЩИТЫ IP40 ВЕС 10 КГ РАБОЧАЯ ТЕМПЕРАТУРА ОТ -40 ДО +85С ТЕМПЕРАТУРА ХРАНЕНИЯ -40 ДО +85C ВЛАЖНОСТЬ ОТ 5 ДО 95% (БЕЗ КОНДЕНСАТА) MTBF 368000 ЧАСОВ ГАРАНТИЯ 5 ЛЕТ | I14: CT | J14: Kyland Technology Co., Ltd. | K14: 156 | L14: отсутствует | M14: KYLAND | N14: шт | O14: Нотификация | P14: 10052 | Q14: =VLOOKUP(C14,Лист1!$B$1:$N$33,5,0) -> RU0000053245 | R14: =VLOOKUP(C14,Лист1!$B$1:$N$33,6,0) -> 44383 | S14: =VLOOKUP(C14,Лист1!$B$1:$N$33,7,0) -> 44383 | T14: =VLOOKUP(C14,Лист1!$B$1:$N$33,8,0) -> 48213 | U14: =VLOOKUP(C14,Лист1!$B$1:$N$33,9,0) -> 10 | V14: =U14*E14 -> 20 | W14: 15 | X14: =W14+W14*0.078 -> 16.17 | Y14: Декларации соответствия | Z14: 01191 | AA14: =VLOOKUP(C14,Лист1!$B$1:$N$33,10,0) -> ЕАЭС N RU Д-CN.КА01.В.23216/20 | AB14: =VLOOKUP(C14,Лист1!$B$1:$N$33,11,0) -> 43908 | AC14: =VLOOKUP(C14,Лист1!$B$1:$N$33,12,0) -> 43908 | AD14: =VLOOKUP(C14,Лист1!$B$1:$N$33,13,0) -> 45733 | AE14: отсутствует | AF14: 10005030/090920/0260337 | AG14: Симанитрон
A15: 44063 | B15: =VLOOKUP(C15,Лист1!$B$1:$N$33,2,0) -> 8517620003 | C15: SM6.6-4GX-1U-S | D15: =VLOOKUP(C15,Лист1!$B$2:$T$45,14,0) -> ПРОМЫШЛЕННЫЕ КОММУТАТОРЫ ДЛЯ УПРАВЛЕНИЯ В СЕТЯХ ETHERNET, НЕ ЛОМ ЭЛЕКТРООБОРУДОВАНИЯ, НЕ ПРЕДНАЗНАЧЕНЫ ДЛЯ НЕГЛАСНОГО ПОЛУЧЕНИЯ ИНФОРМАЦИИ, КОМПЛЕКТУЮЩИЕ ДЛЯ СЕРВЕРОВ И СЕРВЕРНОГО ОБОРУДОВАНИЯ, ГРАЖДАНСКОГО ПРИМЕНЕНИЯ. ПОСТАВЛЯЮТСЯ С клеммными колодками , уголками для крепления в стойку и консольным кабелем. | E15: 2 | F15: 198 | G15: =F15*E15 -> 396 | H15: =VLOOKUP(C15,Лист1!$B$1:$N$33,4,0) -> SICOM3028GPT-L3G-MB-HV-HV-S - ПРОМЫШЛЕННЫЕ КОММУТАТОРЫ С ШИРОКИМ СПЕКТРОМ СФЕР ПРИМЕНЕНИЯ И МОДУЛЬНЫМ ДИЗАЙНОМ ДЛЯ ПРОСТОТЫ МАСШТАБИРОВАНИЯ И РАСШИРЕНИЯ ФУНКЦИОНАЛА УСТРОЙСТВА. SICOM3028GPT-L3G МОГУТ ИМЕТЬ ДО 28 ГИГАБИТНЫХ ПОРТОВ. ПРИ ЭТОМ ВОЗМОЖНА ПРАКТИЧЕСКИ ЛЮБАЯ КОМБИНАЦИЯ МЕДНЫХ И ОПТИЧЕСКИХ ПОРТОВ. ПИТАНИЕ: НАПРЯЖЕНИЕ ПИТАНИЯ: 220VAC/DC (85-264VAC/77-370VDC) МЕХАНИЧЕСКИЕ ХАРАКТЕРИСТИКИ: РАЗМЕРЫ 482.6 X 44 X 360 ММ КРЕПЛЕНИЕ 19" СТОЙКА КЛАСС ЗАЩИТЫ IP40 ВЕС 10 КГ РАБОЧАЯ ТЕМПЕРАТУРА ОТ -40 ДО +85С ТЕМПЕРАТУРА ХРАНЕНИЯ -40 ДО +85C ВЛАЖНОСТЬ ОТ 5 ДО 95% (БЕЗ КОНДЕНСАТА) MTBF 368000 ЧАСОВ ГАРАНТИЯ 5 ЛЕТ | I15: CT | J15: Kyland Technology Co., Ltd. | K15: 156 | L15: отсутствует | M15: KYLAND | N15: шт | O15: Нотификация | P15: 10052 | Q15: =VLOOKUP(C15,Лист1!$B$1:$N$33,5,0) -> RU0000053828 | R15: =VLOOKUP(C15,Лист1!$B$1:$N$33,6,0) -> 44431 | S15: =VLOOKUP(C15,Лист1!$B$1:$N$33,7,0) -> 44431 | T15: =VLOOKUP(C15,Лист1!$B$1:$N$33,8,0) -> 48213 | U15: 0.275 | V15: =U15*E15 -> 0.55 | W15: 0.6 | X15: =W15+W15*0.078 -> 0.6468 | Y15: Декларации соответствия | AE15: отсутствует | AF15: 10005030/090920/0260337 | AG15: Симанитрон
A16: 44063 | B16: =VLOOKUP(C16,Лист1!$B$1:$N$33,2,0) -> 8517620003 | C16: SM6.6-4GE-0.5U-S | D16: =VLOOKUP(C16,Лист1!$B$2:$T$45,14,0) -> ПРОМЫШЛЕННЫЕ КОММУТАТОРЫ ДЛЯ УПРАВЛЕНИЯ В СЕТЯХ ETHERNET, НЕ ЛОМ ЭЛЕКТРООБОРУДОВАНИЯ, НЕ ПРЕДНАЗНАЧЕНЫ ДЛЯ НЕГЛАСНОГО ПОЛУЧЕНИЯ ИНФОРМАЦИИ, КОМПЛЕКТУЮЩИЕ ДЛЯ СЕРВЕРОВ И СЕРВЕРНОГО ОБОРУДОВАНИЯ, ГРАЖДАНСКОГО ПРИМЕНЕНИЯ. ПОСТАВЛЯЮТСЯ С клеммными колодками , уголками для крепления в стойку и консольным кабелем. | E16: 8 | F16: 198 | G16: =F16*E16 -> 1584 | H16: =VLOOKUP(C16,Лист1!$B$1:$N$33,4,0) -> SICOM3028GPT-L3G-MB-HV-HV-S - ПРОМЫШЛЕННЫЕ КОММУТАТОРЫ С ШИРОКИМ СПЕКТРОМ СФЕР ПРИМЕНЕНИЯ И МОДУЛЬНЫМ ДИЗАЙНОМ ДЛЯ ПРОСТОТЫ МАСШТАБИРОВАНИЯ И РАСШИРЕНИЯ ФУНКЦИОНАЛА УСТРОЙСТВА. SICOM3028GPT-L3G МОГУТ ИМЕТЬ ДО 28 ГИГАБИТНЫХ ПОРТОВ. ПРИ ЭТОМ ВОЗМОЖНА ПРАКТИЧЕСКИ ЛЮБАЯ КОМБИНАЦИЯ МЕДНЫХ И ОПТИЧЕСКИХ ПОРТОВ. ПИТАНИЕ: НАПРЯЖЕНИЕ ПИТАНИЯ: 220VAC/DC (85-264VAC/77-370VDC) МЕХАНИЧЕСКИЕ ХАРАКТЕРИСТИКИ: РАЗМЕРЫ 482.6 X 44 X 360 ММ КРЕПЛЕНИЕ 19" СТОЙКА КЛАСС ЗАЩИТЫ IP40 ВЕС 10 КГ РАБОЧАЯ ТЕМПЕРАТУРА ОТ -40 ДО +85С ТЕМПЕРАТУРА ХРАНЕНИЯ -40 ДО +85C ВЛАЖНОСТЬ ОТ 5 ДО 95% (БЕЗ КОНДЕНСАТА) MTBF 368000 ЧАСОВ ГАРАНТИЯ 5 ЛЕТ | I16: CT | J16: Kyland Technology Co., Ltd. | K16: 156 | L16: отсутствует | M16: KYLAND | N16: шт | O16: Нотификация | P16: 10052 | Q16: =VLOOKUP(C16,Лист1!$B$1:$N$33,5,0) -> RU0000053828 | R16: =VLOOKUP(C16,Лист1!$B$1:$N$33,6,0) -> 44431 | S16: =VLOOKUP(C16,Лист1!$B$1:$N$33,7,0) -> 44431 | T16: =VLOOKUP(C16,Лист1!$B$1:$N$33,8,0) -> 48213 | U16: 0.275 | V16: =U16*E16 -> 2.2 | W16: 2.4 | X16: =W16+W16*0.078 -> 2.5872 | Y16: Декларации соответствия | AE16: отсутствует | AF16: 10005030/090920/0260337 | AG16: Симанитрон
A17: 44063 | B17: =VLOOKUP(C17,Лист1!$B$1:$N$33,2,0) -> 8517620003 | C17: SM6.6-4GX-0.5U-S | D17: =VLOOKUP(C17,Лист1!$B$2:$T$45,14,0) -> ПРОМЫШЛЕННЫЕ КОММУТАТОРЫ ДЛЯ УПРАВЛЕНИЯ В СЕТЯХ ETHERNET, НЕ ЛОМ ЭЛЕКТРООБОРУДОВАНИЯ, НЕ ПРЕДНАЗНАЧЕНЫ ДЛЯ НЕГЛАСНОГО ПОЛУЧЕНИЯ ИНФОРМАЦИИ, КОМПЛЕКТУЮЩИЕ ДЛЯ СЕРВЕРОВ И СЕРВЕРНОГО ОБОРУДОВАНИЯ, ГРАЖДАНСКОГО ПРИМЕНЕНИЯ. ПОСТАВЛЯЮТСЯ С клеммными колодками , уголками для крепления в стойку и консольным кабелем. | E17: 4 | F17: 198 | G17: =F17*E17 -> 792 | H17: =VLOOKUP(C17,Лист1!$B$1:$N$33,4,0) -> SICOM3028GPT-L3G-MB-HV-HV-S - ПРОМЫШЛЕННЫЕ КОММУТАТОРЫ С ШИРОКИМ СПЕКТРОМ СФЕР ПРИМЕНЕНИЯ И МОДУЛЬНЫМ ДИЗАЙНОМ ДЛЯ ПРОСТОТЫ МАСШТАБИРОВАНИЯ И РАСШИРЕНИЯ ФУНКЦИОНАЛА УСТРОЙСТВА. SICOM3028GPT-L3G МОГУТ ИМЕТЬ ДО 28 ГИГАБИТНЫХ ПОРТОВ. ПРИ ЭТОМ ВОЗМОЖНА ПРАКТИЧЕСКИ ЛЮБАЯ КОМБИНАЦИЯ МЕДНЫХ И ОПТИЧЕСКИХ ПОРТОВ. ПИТАНИЕ: НАПРЯЖЕНИЕ ПИТАНИЯ: 220VAC/DC (85-264VAC/77-370VDC) МЕХАНИЧЕСКИЕ ХАРАКТЕРИСТИКИ: РАЗМЕРЫ 482.6 X 44 X 360 ММ КРЕПЛЕНИЕ 19" СТОЙКА КЛАСС ЗАЩИТЫ IP40 ВЕС 10 КГ РАБОЧАЯ ТЕМПЕРАТУРА ОТ -40 ДО +85С ТЕМПЕРАТУРА ХРАНЕНИЯ -40 ДО +85C ВЛАЖНОСТЬ ОТ 5 ДО 95% (БЕЗ КОНДЕНСАТА) MTBF 368000 ЧАСОВ ГАРАНТИЯ 5 ЛЕТ | I17: CT | J17: Kyland Technology Co., Ltd. | K17: 156 | L17: отсутствует | M17: KYLAND | N17: шт | O17: Нотификация | P17: 10052 | Q17: =VLOOKUP(C17,Лист1!$B$1:$N$33,5,0) -> RU0000053828 | R17: =VLOOKUP(C17,Лист1!$B$1:$N$33,6,0) -> 44431 | S17: =VLOOKUP(C17,Лист1!$B$1:$N$33,7,0) -> 44431 | T17: =VLOOKUP(C17,Лист1!$B$1:$N$33,8,0) -> 48213 | U17: 0.275 | V17: =U17*E17 -> 1.1 | W17: 1.2 | X17: =W17+W17*0.078 -> 1.2936 | Y17: Декларации соответствия | AE17: отсутствует | AF17: 10005030/090920/0260337 | AG17: Симанитрон
A18: 44063 | B18: =VLOOKUP(C18,Лист1!$B$1:$N$33,2,0) -> 8517620003 | C18: KPS2204-2T4D-L3-L3-S | D18: =VLOOKUP(C18,Лист1!$B$2:$T$45,14,0) -> ПРОМЫШЛЕННЫЕ КОММУТАТОРЫ ДЛЯ УПРАВЛЕНИЯ В СЕТЯХ ETHERNET, НЕ ЛОМ ЭЛЕКТРООБОРУДОВАНИЯ, НЕ ПРЕДНАЗНАЧЕНЫ ДЛЯ НЕГЛАСНОГО ПОЛУЧЕНИЯ ИНФОРМАЦИИ, КОМПЛЕКТУЮЩИЕ ДЛЯ СЕРВЕРОВ И СЕРВЕРНОГО ОБОРУДОВАНИЯ, ГРАЖДАНСКОГО ПРИМЕНЕНИЯ. ПОСТАВЛЯЮТСЯ С клеммными колодками , уголками для крепления в стойку и консольным кабелем. | E18: 2 | F18: 291 | G18: =F18*E18 -> 582 | H18: =VLOOKUP(C18,Лист1!$B$1:$N$33,4,0) -> SICOM3028GPT-L3G-MB-HV-HV-S - ПРОМЫШЛЕННЫЕ КОММУТАТОРЫ С ШИРОКИМ СПЕКТРОМ СФЕР ПРИМЕНЕНИЯ И МОДУЛЬНЫМ ДИЗАЙНОМ ДЛЯ ПРОСТОТЫ МАСШТАБИРОВАНИЯ И РАСШИРЕНИЯ ФУНКЦИОНАЛА УСТРОЙСТВА. SICOM3028GPT-L3G МОГУТ ИМЕТЬ ДО 28 ГИГАБИТНЫХ ПОРТОВ. ПРИ ЭТОМ ВОЗМОЖНА ПРАКТИЧЕСКИ ЛЮБАЯ КОМБИНАЦИЯ МЕДНЫХ И ОПТИЧЕСКИХ ПОРТОВ. ПИТАНИЕ: НАПРЯЖЕНИЕ ПИТАНИЯ: 220VAC/DC (85-264VAC/77-370VDC) МЕХАНИЧЕСКИЕ ХАРАКТЕРИСТИКИ: РАЗМЕРЫ 482.6 X 44 X 360 ММ КРЕПЛЕНИЕ 19" СТОЙКА КЛАСС ЗАЩИТЫ IP40 ВЕС 10 КГ РАБОЧАЯ ТЕМПЕРАТУРА ОТ -40 ДО +85С ТЕМПЕРАТУРА ХРАНЕНИЯ -40 ДО +85C ВЛАЖНОСТЬ ОТ 5 ДО 95% (БЕЗ КОНДЕНСАТА) MTBF 368000 ЧАСОВ ГАРАНТИЯ 5 ЛЕТ | I18: CT | J18: Kyland Technology Co., Ltd. | K18: 156 | L18: отсутствует | M18: KYLAND | N18: шт | O18: Нотификация | P18: 10052 | Q18: =VLOOKUP(C18,Лист1!$B$1:$N$33,5,0) -> RU0000033119 | R18: =VLOOKUP(C18,Лист1!$B$1:$N$33,6,0) -> 42972 | S18: =VLOOKUP(C18,Лист1!$B$1:$N$33,7,0) -> 42972 | T18: =VLOOKUP(C18,Лист1!$B$1:$N$33,8,0) -> 44369 | U18: 0.69 | V18: =U18*E18 -> 1.38 | W18: 2 | X18: =W18+W18*0.078 -> 2.156 | Y18: Декларации соответствия | AE18: отсутствует | AF18: 10005030/090920/0260337 | AG18: Симанитрон
A19: 44063 | B19: =VLOOKUP(C19,Лист1!$B$1:$N$33,2,0) -> 8517620003 | C19: SICOM3024P-4GX24T-HV-HV-S | D19: =VLOOKUP(C19,Лист1!$B$2:$T$45,14,0) -> ПРОМЫШЛЕННЫЕ КОММУТАТОРЫ ДЛЯ УПРАВЛЕНИЯ В СЕТЯХ ETHERNET, НЕ ЛОМ ЭЛЕКТРООБОРУДОВАНИЯ, НЕ ПРЕДНАЗНАЧЕНЫ ДЛЯ НЕГЛАСНОГО ПОЛУЧЕНИЯ ИНФОРМАЦИИ, КОМПЛЕКТУЮЩИЕ ДЛЯ СЕРВЕРОВ И СЕРВЕРНОГО ОБОРУДОВАНИЯ, ГРАЖДАНСКОГО ПРИМЕНЕНИЯ. ПОСТАВЛЯЮТСЯ С клеммными колодками , уголками для крепления в стойку и консольным кабелем. | E19: 10 | F19: 894 | G19: =F19*E19 -> 8940 | H19: =VLOOKUP(C19,Лист1!$B$1:$N$33,4,0) -> Описание SICOM3024P-4GX24T-HV-HV-S - промышленные коммутаторы 2 уровня, монтируемые в 19" стойку. Устройства имеют 4 гигабитных порта и 24 порта 100 Мбит/с, которые могут быть как медными так и оптическими. Коммутаторы крепятся в 19-дюймовую стойку (занимают 1U). Устройства соответствуют IEC61850-3, IEEE1613, EN50155, EN50121-4, NEMA TS-2 для использования в энергетике и на транспорте. Диапазон рабочих температур коммутаторов SICOM3024P-2M26T-SC05-HV-HV-S от -40° до +85°. Характеристики Протоколы DT-Ring, DT-Ring+, MSTP IGMP Snooping, GMRP; VLAN, PVLAN; Telnet, HTTP, HTTPS, SNMPv1/v2/v3, RMON, LLDP, DHCP server; SNTP, RTC; DT-Psec, SSH, SSL, ACL; ARP, QoS Пропускная способность устройства 9.5 Mpps Питание Напряжение питания От 85 до264Вольт переменного тока или от 77 до 300Вольт постоянного тока Потребляемая мощность менее 30 Вт Механические характеристики Размеры 482.6×44×322.5 мм Крепление 19” стойка Класс защиты IP40 Рабочая температура от -40 до +85С Температура хранения -40 до +85C Влажность от 5 до 95% (без конденсата) MTBF 346889 часов Гарантия 5 лет | I19: CT | J19: Kyland Technology Co., Ltd. | K19: 156 | L19: отсутствует | M19: KYLAND | N19: шт | O19: Нотификация | P19: 10052 | Q19: =VLOOKUP(C19,Лист1!$B$1:$N$33,5,0) -> RU0000053826 | R19: =VLOOKUP(C19,Лист1!$B$1:$N$33,6,0) -> 44431 | S19: =VLOOKUP(C19,Лист1!$B$1:$N$33,7,0) -> 44431 | T19: =VLOOKUP(C19,Лист1!$B$1:$N$33,8,0) -> 48213 | U19: 5.22 | V19: =U19*E19 -> 52.2 | W19: 60 | X19: =W19+W19*0.078 -> 64.68 | Y19: Декларации соответствия | Z19: 01191 | AA19: =VLOOKUP(C19,Лист1!$B$1:$N$33,10,0) -> ЕАЭС N RU Д-CN.КА01.В.17403/19 | AB19: =VLOOKUP(C19,Лист1!$B$1:$N$33,11,0) -> 43787 | AC19: =VLOOKUP(C19,Лист1!$B$1:$N$33,12,0) -> 43787 | AD19: =VLOOKUP(C19,Лист1!$B$1:$N$33,13,0) -> 45613 | AE19: отсутствует | AF19: 10005030/090920/0260337 | AG19: Симанитрон
A20: 44063 | B20: =VLOOKUP(C20,Лист1!$B$1:$N$33,2,0) -> 8517620003 | C20: SICOM3009A-8T-L2-L2-S | D20: =VLOOKUP(C20,Лист1!$B$2:$T$45,14,0) -> ПРОМЫШЛЕННЫЕ КОММУТАТОРЫ ДЛЯ УПРАВЛЕНИЯ В СЕТЯХ ETHERNET, НЕ ЛОМ ЭЛЕКТРООБОРУДОВАНИЯ, НЕ ПРЕДНАЗНАЧЕНЫ ДЛЯ НЕГЛАСНОГО ПОЛУЧЕНИЯ ИНФОРМАЦИИ, КОМПЛЕКТУЮЩИЕ ДЛЯ СЕРВЕРОВ И СЕРВЕРНОГО ОБОРУДОВАНИЯ, ГРАЖДАНСКОГО ПРИМЕНЕНИЯ. ПОСТАВЛЯЮТСЯ С клеммными колодками , уголками для крепления в стойку и консольным кабелем. | E20: 1 | F20: 331 | G20: =F20*E20 -> 331 | H20: =VLOOKUP(C20,Лист1!$B$1:$N$33,4,0) -> SICOM3028GPT-L3G-MB-HV-HV-S - ПРОМЫШЛЕННЫЕ КОММУТАТОРЫ С ШИРОКИМ СПЕКТРОМ СФЕР ПРИМЕНЕНИЯ И МОДУЛЬНЫМ ДИЗАЙНОМ ДЛЯ ПРОСТОТЫ МАСШТАБИРОВАНИЯ И РАСШИРЕНИЯ ФУНКЦИОНАЛА УСТРОЙСТВА. SICOM3028GPT-L3G МОГУТ ИМЕТЬ ДО 28 ГИГАБИТНЫХ ПОРТОВ. ПРИ ЭТОМ ВОЗМОЖНА ПРАКТИЧЕСКИ ЛЮБАЯ КОМБИНАЦИЯ МЕДНЫХ И ОПТИЧЕСКИХ ПОРТОВ. ПИТАНИЕ: НАПРЯЖЕНИЕ ПИТАНИЯ: 220VAC/DC (85-264VAC/77-370VDC) МЕХАНИЧЕСКИЕ ХАРАКТЕРИСТИКИ: РАЗМЕРЫ 482.6 X 44 X 360 ММ КРЕПЛЕНИЕ 19" СТОЙКА КЛАСС ЗАЩИТЫ IP40 ВЕС 10 КГ РАБОЧАЯ ТЕМПЕРАТУРА ОТ -40 ДО +85С ТЕМПЕРАТУРА ХРАНЕНИЯ -40 ДО +85C ВЛАЖНОСТЬ ОТ 5 ДО 95% (БЕЗ КОНДЕНСАТА) MTBF 368000 ЧАСОВ ГАРАНТИЯ 5 ЛЕТ | I20: CT | J20: Kyland Technology Co., Ltd. | K20: 156 | L20: отсутствует | M20: KYLAND | N20: шт | O20: Нотификация | P20: 10052 | Q20: =VLOOKUP(C20,Лист1!$B$1:$N$33,5,0) -> RU0000033119 | R20: =VLOOKUP(C20,Лист1!$B$1:$N$33,6,0) -> 42972 | S20: =VLOOKUP(C20,Лист1!$B$1:$N$33,7,0) -> 42972 | T20: =VLOOKUP(C20,Лист1!$B$1:$N$33,8,0) -> 44369 | U20: =VLOOKUP(C20,Лист1!$B$1:$N$33,9,0) -> 0.76 | V20: =U20*E20 -> 0.76 | W20: 1.3 | X20: 1.45 | Y20: Декларации соответствия | AB20: =VLOOKUP(C20,Лист1!$B$1:$N$33,11,0) -> не требеутся | AC20: =VLOOKUP(C20,Лист1!$B$1:$N$33,12,0) -> не требеутся | AD20: =VLOOKUP(C20,Лист1!$B$1:$N$33,13,0) -> не требеутся | AE20: отсутствует | AF20: 10005030/090920/0260337 | AG20: Симанитрон
A21: 44075 | B21: =VLOOKUP(C21,Лист1!$B$1:$N$33,2,0) -> 8517620003 | C21: SICOM3216-16T-L2-L2-S | D21: =VLOOKUP(C21,Лист1!$B$2:$T$45,14,0) -> ПРОМЫШЛЕННЫЕ КОММУТАТОРЫ ДЛЯ УПРАВЛЕНИЯ В СЕТЯХ ETHERNET, НЕ ЛОМ ЭЛЕКТРООБОРУДОВАНИЯ, НЕ ПРЕДНАЗНАЧЕНЫ ДЛЯ НЕГЛАСНОГО ПОЛУЧЕНИЯ ИНФОРМАЦИИ, КОМПЛЕКТУЮЩИЕ ДЛЯ СЕРВЕРОВ И СЕРВЕРНОГО ОБОРУДОВАНИЯ, ГРАЖДАНСКОГО ПРИМЕНЕНИЯ. ПОСТАВЛЯЮТСЯ С клеммными колодками , уголками для крепления в стойку и консольным кабелем. | E21: 2 | F21: 499.5 | G21: =F21*E21 -> 999 | H21: =VLOOKUP(C21,Лист1!$B$1:$N$33,4,0) -> SICOM3028GPT-L3G-MB-HV-HV-S - ПРОМЫШЛЕННЫЕ КОММУТАТОРЫ С ШИРОКИМ СПЕКТРОМ СФЕР ПРИМЕНЕНИЯ И МОДУЛЬНЫМ ДИЗАЙНОМ ДЛЯ ПРОСТОТЫ МАСШТАБИРОВАНИЯ И РАСШИРЕНИЯ ФУНКЦИОНАЛА УСТРОЙСТВА. SICOM3028GPT-L3G МОГУТ ИМЕТЬ ДО 28 ГИГАБИТНЫХ ПОРТОВ. ПРИ ЭТОМ ВОЗМОЖНА ПРАКТИЧЕСКИ ЛЮБАЯ КОМБИНАЦИЯ МЕДНЫХ И ОПТИЧЕСКИХ ПОРТОВ. ПИТАНИЕ: НАПРЯЖЕНИЕ ПИТАНИЯ: 220VAC/DC (85-264VAC/77-370VDC) МЕХАНИЧЕСКИЕ ХАРАКТЕРИСТИКИ: РАЗМЕРЫ 482.6 X 44 X 360 ММ КРЕПЛЕНИЕ 19" СТОЙКА КЛАСС ЗАЩИТЫ IP40 ВЕС 10 КГ РАБОЧАЯ ТЕМПЕРАТУРА ОТ -40 ДО +85С ТЕМПЕРАТУРА ХРАНЕНИЯ -40 ДО +85C ВЛАЖНОСТЬ ОТ 5 ДО 95% (БЕЗ КОНДЕНСАТА) MTBF 368000 ЧАСОВ ГАРАНТИЯ 5 ЛЕТ | I21: CT | J21: Kyland Technology Co., Ltd. | K21: 156 | L21: отсутствует | M21: KYLAND | N21: шт | O21: Нотификация | P21: 10052 | Q21: =VLOOKUP(C21,Лист1!$B$1:$N$33,5,0) -> RU0000033119 | R21: =VLOOKUP(C21,Лист1!$B$1:$N$33,6,0) -> 42972 | S21: =VLOOKUP(C21,Лист1!$B$1:$N$33,7,0) -> 42972 | T21: =VLOOKUP(C21,Лист1!$B$1:$N$33,8,0) -> 44369 | U21: =VLOOKUP(C21,Лист1!$B$1:$N$33,9,0) -> 0.76 | W21: 4.9 | X21: 6 | Y21: Декларации соответствия | Z21: 01191 | AB21: =VLOOKUP(C21,Лист1!$B$1:$N$33,11,0) -> не требеутся | AC21: =VLOOKUP(C21,Лист1!$B$1:$N$33,12,0) -> не требеутся | AD21: =VLOOKUP(C21,Лист1!$B$1:$N$33,13,0) -> не требеутся | AE21: отсутствует | AF21: 10005030/170920/0270653 | AG21: Симанитрон
A22: 44082 | B22: =VLOOKUP(C22,Лист1!$B$1:$N$33,2,0) -> 8517620003 | C22: SICOM3009A-1S7T-SC40-L2-L2-S | D22: =VLOOKUP(C22,Лист1!$B$2:$T$45,14,0) -> ПРОМЫШЛЕННЫЕ КОММУТАТОРЫ ДЛЯ УПРАВЛЕНИЯ В СЕТЯХ ETHERNET, НЕ ЛОМ ЭЛЕКТРООБОРУДОВАНИЯ, НЕ ПРЕДНАЗНАЧЕНЫ ДЛЯ НЕГЛАСНОГО ПОЛУЧЕНИЯ ИНФОРМАЦИИ, КОМПЛЕКТУЮЩИЕ ДЛЯ СЕРВЕРОВ И СЕРВЕРНОГО ОБОРУДОВАНИЯ, ГРАЖДАНСКОГО ПРИМЕНЕНИЯ. ПОСТАВЛЯЮТСЯ С клеммными колодками , уголками для крепления в стойку и консольным кабелем. | E22: 10 | F22: 396 | G22: =F22*E22 -> 3960 | H22: =VLOOKUP(C22,Лист1!$B$1:$N$33,4,0) -> SICOM3028GPT-L3G-MB-HV-HV-S - ПРОМЫШЛЕННЫЕ КОММУТАТОРЫ С ШИРОКИМ СПЕКТРОМ СФЕР ПРИМЕНЕНИЯ И МОДУЛЬНЫМ ДИЗАЙНОМ ДЛЯ ПРОСТОТЫ МАСШТАБИРОВАНИЯ И РАСШИРЕНИЯ ФУНКЦИОНАЛА УСТРОЙСТВА. SICOM3028GPT-L3G МОГУТ ИМЕТЬ ДО 28 ГИГАБИТНЫХ ПОРТОВ. ПРИ ЭТОМ ВОЗМОЖНА ПРАКТИЧЕСКИ ЛЮБАЯ КОМБИНАЦИЯ МЕДНЫХ И ОПТИЧЕСКИХ ПОРТОВ. ПИТАНИЕ: НАПРЯЖЕНИЕ ПИТАНИЯ: 220VAC/DC (85-264VAC/77-370VDC) МЕХАНИЧЕСКИЕ ХАРАКТЕРИСТИКИ: РАЗМЕРЫ 482.6 X 44 X 360 ММ КРЕПЛЕНИЕ 19" СТОЙКА КЛАСС ЗАЩИТЫ IP40 ВЕС 10 КГ РАБОЧАЯ ТЕМПЕРАТУРА ОТ -40 ДО +85С ТЕМПЕРАТУРА ХРАНЕНИЯ -40 ДО +85C ВЛАЖНОСТЬ ОТ 5 ДО 95% (БЕЗ КОНДЕНСАТА) MTBF 368000 ЧАСОВ ГАРАНТИЯ 5 ЛЕТ | I22: CT | J22: Kyland Technology Co., Ltd. | K22: 156 | L22: отсутствует | M22: KYLAND | N22: шт | O22: Нотификация | P22: 10052 | Q22: =VLOOKUP(C22,Лист1!$B$1:$N$33,5,0) -> RU0000033118 | R22: =VLOOKUP(C22,Лист1!$B$1:$N$33,6,0) -> 42972 | S22: =VLOOKUP(C22,Лист1!$B$1:$N$33,7,0) -> 42972 | T22: =VLOOKUP(C22,Лист1!$B$1:$N$33,8,0) -> 44369 | U22: =VLOOKUP(C22,Лист1!$B$1:$N$33,9,0) -> 0.76 | V22: =U22*E22 -> 7.6 | W22: 13 | X22: =W22+W22*0.06 -> 13.78 | Y22: Декларации соответствия | Z22: 01191 | AB22: =VLOOKUP(C22,Лист1!$B$1:$N$33,11,0) -> не требеутся | AC22: =VLOOKUP(C22,Лист1!$B$1:$N$33,12,0) -> не требеутся | AD22: =VLOOKUP(C22,Лист1!$B$1:$N$33,13,0) -> не требеутся | AE22: отсутствует | AF22: 10005030/210920/0274803 | AG22: Симанитрон
A23: 44082 | B23: =VLOOKUP(C23,Лист1!$B$1:$N$33,2,0) -> 8517620003 | C23: SICOM3009A-8T-L2-L2-S | D23: =VLOOKUP(C23,Лист1!$B$2:$T$45,14,0) -> ПРОМЫШЛЕННЫЕ КОММУТАТОРЫ ДЛЯ УПРАВЛЕНИЯ В СЕТЯХ ETHERNET, НЕ ЛОМ ЭЛЕКТРООБОРУДОВАНИЯ, НЕ ПРЕДНАЗНАЧЕНЫ ДЛЯ НЕГЛАСНОГО ПОЛУЧЕНИЯ ИНФОРМАЦИИ, КОМПЛЕКТУЮЩИЕ ДЛЯ СЕРВЕРОВ И СЕРВЕРНОГО ОБОРУДОВАНИЯ, ГРАЖДАНСКОГО ПРИМЕНЕНИЯ. ПОСТАВЛЯЮТСЯ С клеммными колодками , уголками для крепления в стойку и консольным кабелем. | E23: 6 | F23: 331 | G23: =F23*E23 -> 1986 | H23: =VLOOKUP(C23,Лист1!$B$1:$N$33,4,0) -> SICOM3028GPT-L3G-MB-HV-HV-S - ПРОМЫШЛЕННЫЕ КОММУТАТОРЫ С ШИРОКИМ СПЕКТРОМ СФЕР ПРИМЕНЕНИЯ И МОДУЛЬНЫМ ДИЗАЙНОМ ДЛЯ ПРОСТОТЫ МАСШТАБИРОВАНИЯ И РАСШИРЕНИЯ ФУНКЦИОНАЛА УСТРОЙСТВА. SICOM3028GPT-L3G МОГУТ ИМЕТЬ ДО 28 ГИГАБИТНЫХ ПОРТОВ. ПРИ ЭТОМ ВОЗМОЖНА ПРАКТИЧЕСКИ ЛЮБАЯ КОМБИНАЦИЯ МЕДНЫХ И ОПТИЧЕСКИХ ПОРТОВ. ПИТАНИЕ: НАПРЯЖЕНИЕ ПИТАНИЯ: 220VAC/DC (85-264VAC/77-370VDC) МЕХАНИЧЕСКИЕ ХАРАКТЕРИСТИКИ: РАЗМЕРЫ 482.6 X 44 X 360 ММ КРЕПЛЕНИЕ 19" СТОЙКА КЛАСС ЗАЩИТЫ IP40 ВЕС 10 КГ РАБОЧАЯ ТЕМПЕРАТУРА ОТ -40 ДО +85С ТЕМПЕРАТУРА ХРАНЕНИЯ -40 ДО +85C ВЛАЖНОСТЬ ОТ 5 ДО 95% (БЕЗ КОНДЕНСАТА) MTBF 368000 ЧАСОВ ГАРАНТИЯ 5 ЛЕТ | I23: CT | J23: Kyland Technology Co., Ltd. | K23: 156 | L23: отсутствует | M23: KYLAND | N23: шт | O23: Нотификация | P23: 10052 | Q23: =VLOOKUP(C23,Лист1!$B$1:$N$33,5,0) -> RU0000033119 | R23: =VLOOKUP(C23,Лист1!$B$1:$N$33,6,0) -> 42972 | S23: =VLOOKUP(C23,Лист1!$B$1:$N$33,7,0) -> 42972 | T23: =VLOOKUP(C23,Лист1!$B$1:$N$33,8,0) -> 44369 | U23: =VLOOKUP(C23,Лист1!$B$1:$N$33,9,0) -> 0.76 | V23: =U23*E23 -> 4.56 | W23: 7.8 | X23: 8.22 | Y23: Декларации соответствия | Z23: 01191 | AB23: =VLOOKUP(C23,Лист1!$B$1:$N$33,11,0) -> не требеутся | AC23: =VLOOKUP(C23,Лист1!$B$1:$N$33,12,0) -> не требеутся | AD23: =VLOOKUP(C23,Лист1!$B$1:$N$33,13,0) -> не требеутся | AE23: отсутствует | AF23: 10005030/210920/0274803 | AG23: Симанитрон
A24: 44125 | B24: =VLOOKUP(C24,Лист1!$B$1:$N$33,2,0) -> 8517620003 | C24: SICOM3000-2S6T-SC40-L2-L2-S | D24: =VLOOKUP(C24,Лист1!$B$2:$T$45,14,0) -> ПРОМЫШЛЕННЫЕ КОММУТАТОРЫ ДЛЯ УПРАВЛЕНИЯ В СЕТЯХ ETHERNET, НЕ ЛОМ ЭЛЕКТРООБОРУДОВАНИЯ, НЕ ПРЕДНАЗНАЧЕНЫ ДЛЯ НЕГЛАСНОГО ПОЛУЧЕНИЯ ИНФОРМАЦИИ, КОМПЛЕКТУЮЩИЕ ДЛЯ СЕРВЕРОВ И СЕРВЕРНОГО ОБОРУДОВАНИЯ, ГРАЖДАНСКОГО ПРИМЕНЕНИЯ. ПОСТАВЛЯЮТСЯ С клеммными колодками , уголками для крепления в стойку и консольным кабелем. | E24: 68 | F24: 250.33 | G24: =F24*E24 -> 17022.44 | H24: =VLOOKUP(C24,Лист1!$B$1:$N$33,4,0) -> SICOM3028GPT-L3G-MB-HV-HV-S - ПРОМЫШЛЕННЫЕ КОММУТАТОРЫ С ШИРОКИМ СПЕКТРОМ СФЕР ПРИМЕНЕНИЯ И МОДУЛЬНЫМ ДИЗАЙНОМ ДЛЯ ПРОСТОТЫ МАСШТАБИРОВАНИЯ И РАСШИРЕНИЯ ФУНКЦИОНАЛА УСТРОЙСТВА. SICOM3028GPT-L3G МОГУТ ИМЕТЬ ДО 28 ГИГАБИТНЫХ ПОРТОВ. ПРИ ЭТОМ ВОЗМОЖНА ПРАКТИЧЕСКИ ЛЮБАЯ КОМБИНАЦИЯ МЕДНЫХ И ОПТИЧЕСКИХ ПОРТОВ. ПИТАНИЕ: НАПРЯЖЕНИЕ ПИТАНИЯ: 220VAC/DC (85-264VAC/77-370VDC) МЕХАНИЧЕСКИЕ ХАРАКТЕРИСТИКИ: РАЗМЕРЫ 482.6 X 44 X 360 ММ КРЕПЛЕНИЕ 19" СТОЙКА КЛАСС ЗАЩИТЫ IP40 ВЕС 10 КГ РАБОЧАЯ ТЕМПЕРАТУРА ОТ -40 ДО +85С ТЕМПЕРАТУРА ХРАНЕНИЯ -40 ДО +85C ВЛАЖНОСТЬ ОТ 5 ДО 95% (БЕЗ КОНДЕНСАТА) MTBF 368000 ЧАСОВ ГАРАНТИЯ 5 ЛЕТ | I24: CT | J24: Kyland Technology Co., Ltd. | K24: 156 | L24: отсутствует | M24: KYLAND | N24: шт | O24: Нотификация | P24: 10052 | Q24: =VLOOKUP(C24,Лист1!$B$1:$N$33,5,0) -> RU0000033118 | R24: =VLOOKUP(C24,Лист1!$B$1:$N$33,6,0) -> 42972 | S24: =VLOOKUP(C24,Лист1!$B$1:$N$33,7,0) -> 42972 | T24: =VLOOKUP(C24,Лист1!$B$1:$N$33,8,0) -> 44369 | U24: 1.5 | V24: =U24*E24 -> 102 | W24: 103 | X24: 107.27 | Y24: Декларация о соответствии | AE24: отсутствует | AF24: 10005030/031120/0330735 | AG24: Симанитрон
A25: 44125 | B25: =VLOOKUP(C25,Лист1!$B$1:$N$33,2,0) -> 8517620003 | C25: SYM3000A-8T-L2-L2 | D25: =VLOOKUP(C25,Лист1!$B$2:$T$45,14,0) -> ПРОМЫШЛЕННЫЕ КОММУТАТОРЫ ДЛЯ УПРАВЛЕНИЯ В СЕТЯХ ETHERNET, НЕ ЛОМ ЭЛЕКТРООБОРУДОВАНИЯ, НЕ ПРЕДНАЗНАЧЕНЫ ДЛЯ НЕГЛАСНОГО ПОЛУЧЕНИЯ ИНФОРМАЦИИ, КОМПЛЕКТУЮЩИЕ ДЛЯ СЕРВЕРОВ И СЕРВЕРНОГО ОБОРУДОВАНИЯ, ГРАЖДАНСКОГО ПРИМЕНЕНИЯ. ПОСТАВЛЯЮТСЯ С клеммными колодками , уголками для крепления в стойку и консольным кабелем. | E25: 16 | F25: 195.08 | G25: =F25*E25 -> 3121.28 | H25: =VLOOKUP(C25,Лист1!$B$1:$N$33,4,0) -> SICOM3028GPT-L3G-MB-HV-HV-S - ПРОМЫШЛЕННЫЕ КОММУТАТОРЫ С ШИРОКИМ СПЕКТРОМ СФЕР ПРИМЕНЕНИЯ И МОДУЛЬНЫМ ДИЗАЙНОМ ДЛЯ ПРОСТОТЫ МАСШТАБИРОВАНИЯ И РАСШИРЕНИЯ ФУНКЦИОНАЛА УСТРОЙСТВА. SICOM3028GPT-L3G МОГУТ ИМЕТЬ ДО 28 ГИГАБИТНЫХ ПОРТОВ. ПРИ ЭТОМ ВОЗМОЖНА ПРАКТИЧЕСКИ ЛЮБАЯ КОМБИНАЦИЯ МЕДНЫХ И ОПТИЧЕСКИХ ПОРТОВ. ПИТАНИЕ: НАПРЯЖЕНИЕ ПИТАНИЯ: 220VAC/DC (85-264VAC/77-370VDC) МЕХАНИЧЕСКИЕ ХАРАКТЕРИСТИКИ: РАЗМЕРЫ 482.6 X 44 X 360 ММ КРЕПЛЕНИЕ 19" СТОЙКА КЛАСС ЗАЩИТЫ IP40 ВЕС 10 КГ РАБОЧАЯ ТЕМПЕРАТУРА ОТ -40 ДО +85С ТЕМПЕРАТУРА ХРАНЕНИЯ -40 ДО +85C ВЛАЖНОСТЬ ОТ 5 ДО 95% (БЕЗ КОНДЕНСАТА) MTBF 368000 ЧАСОВ ГАРАНТИЯ 5 ЛЕТ | I25: CT | J25: Kyland Technology Co., Ltd. | K25: 156 | L25: отсутствует | M25: KYLAND | N25: шт | O25: Нотификация | P25: 10052 | Q25: =VLOOKUP(C25,Лист1!$B$1:$N$33,5,0) -> RU0000049917 | R25: =VLOOKUP(C25,Лист1!$B$1:$N$33,6,0) -> 44099 | S25: =VLOOKUP(C25,Лист1!$B$1:$N$33,7,0) -> 44099 | T25: =VLOOKUP(C25,Лист1!$B$1:$N$33,8,0) -> 47848 | U25: =VLOOKUP(C25,Лист1!$B$1:$N$33,9,0) -> 1.1 | V25: =U25*E25 -> 17.6 | W25: 24 | X25: =W25+W25*0.05 -> 25.2 | Y25: Декларация о соответствии | AE25: отсутствует | AF25: 10005030/031120/0330735 | AG25: Симанитрон
A26: 44125 | B26: =VLOOKUP(C26,Лист1!$B$1:$N$33,2,0) -> 8517620003 | C26: SYM3000A-2SFP8T-L2-L2 | D26: =VLOOKUP(C26,Лист1!$B$2:$T$45,14,0) -> ПРОМЫШЛЕННЫЕ КОММУТАТОРЫ ДЛЯ УПРАВЛЕНИЯ В СЕТЯХ ETHERNET, НЕ ЛОМ ЭЛЕКТРООБОРУДОВАНИЯ, НЕ ПРЕДНАЗНАЧЕНЫ ДЛЯ НЕГЛАСНОГО ПОЛУЧЕНИЯ ИНФОРМАЦИИ, КОМПЛЕКТУЮЩИЕ ДЛЯ СЕРВЕРОВ И СЕРВЕРНОГО ОБОРУДОВАНИЯ, ГРАЖДАНСКОГО ПРИМЕНЕНИЯ. ПОСТАВЛЯЮТСЯ С клеммными колодками , уголками для крепления в стойку и консольным кабелем. | E26: 3 | F26: 250.33 | G26: =F26*E26 -> 750.99 | H26: =VLOOKUP(C26,Лист1!$B$1:$N$33,4,0) -> SICOM3028GPT-L3G-MB-HV-HV-S - ПРОМЫШЛЕННЫЕ КОММУТАТОРЫ С ШИРОКИМ СПЕКТРОМ СФЕР ПРИМЕНЕНИЯ И МОДУЛЬНЫМ ДИЗАЙНОМ ДЛЯ ПРОСТОТЫ МАСШТАБИРОВАНИЯ И РАСШИРЕНИЯ ФУНКЦИОНАЛА УСТРОЙСТВА. SICOM3028GPT-L3G МОГУТ ИМЕТЬ ДО 28 ГИГАБИТНЫХ ПОРТОВ. ПРИ ЭТОМ ВОЗМОЖНА ПРАКТИЧЕСКИ ЛЮБАЯ КОМБИНАЦИЯ МЕДНЫХ И ОПТИЧЕСКИХ ПОРТОВ. ПИТАНИЕ: НАПРЯЖЕНИЕ ПИТАНИЯ: 220VAC/DC (85-264VAC/77-370VDC) МЕХАНИЧЕСКИЕ ХАРАКТЕРИСТИКИ: РАЗМЕРЫ 482.6 X 44 X 360 ММ КРЕПЛЕНИЕ 19" СТОЙКА КЛАСС ЗАЩИТЫ IP40 ВЕС 10 КГ РАБОЧАЯ ТЕМПЕРАТУРА ОТ -40 ДО +85С ТЕМПЕРАТУРА ХРАНЕНИЯ -40 ДО +85C ВЛАЖНОСТЬ ОТ 5 ДО 95% (БЕЗ КОНДЕНСАТА) MTBF 368000 ЧАСОВ ГАРАНТИЯ 5 ЛЕТ | I26: CT | J26: Kyland Technology Co., Ltd. | K26: 156 | L26: отсутствует | M26: KYLAND | N26: шт | O26: Нотификация | P26: 10052 | Q26: =VLOOKUP(C26,Лист1!$B$1:$N$33,5,0) -> RU0000049917 | R26: =VLOOKUP(C26,Лист1!$B$1:$N$33,6,0) -> 44099 | S26: =VLOOKUP(C26,Лист1!$B$1:$N$33,7,0) -> 44099 | T26: =VLOOKUP(C26,Лист1!$B$1:$N$33,8,0) -> 47848 | U26: =VLOOKUP(C26,Лист1!$B$1:$N$33,9,0) -> 1.5 | V26: =U26*E26 -> 4.5 | W26: 4.5 | X26: =W26+W26*0.05 -> 4.725 | Y26: Декларация о соответствии | AE26: отсутствует | AF26: 10005030/031120/0330735 | AG26: Симанитрон
A27: 44125 | B27: =VLOOKUP(C27,Лист1!$B$1:$N$33,2,0) -> 8517620003 | C27: SYM3000A-4SFP16T-L2-L2 | D27: =VLOOKUP(C27,Лист1!$B$2:$T$45,14,0) -> ПРОМЫШЛЕННЫЕ КОММУТАТОРЫ ДЛЯ УПРАВЛЕНИЯ В СЕТЯХ ETHERNET, НЕ ЛОМ ЭЛЕКТРООБОРУДОВАНИЯ, НЕ ПРЕДНАЗНАЧЕНЫ ДЛЯ НЕГЛАСНОГО ПОЛУЧЕНИЯ ИНФОРМАЦИИ, КОМПЛЕКТУЮЩИЕ ДЛЯ СЕРВЕРОВ И СЕРВЕРНОГО ОБОРУДОВАНИЯ, ГРАЖДАНСКОГО ПРИМЕНЕНИЯ. ПОСТАВЛЯЮТСЯ С клеммными колодками , уголками для крепления в стойку и консольным кабелем. | E27: 9 | F27: 424.58 | G27: =F27*E27 -> 3821.22 | H27: =VLOOKUP(C27,Лист1!$B$1:$N$33,4,0) -> SICOM3028GPT-L3G-MB-HV-HV-S - ПРОМЫШЛЕННЫЕ КОММУТАТОРЫ С ШИРОКИМ СПЕКТРОМ СФЕР ПРИМЕНЕНИЯ И МОДУЛЬНЫМ ДИЗАЙНОМ ДЛЯ ПРОСТОТЫ МАСШТАБИРОВАНИЯ И РАСШИРЕНИЯ ФУНКЦИОНАЛА УСТРОЙСТВА. SICOM3028GPT-L3G МОГУТ ИМЕТЬ ДО 28 ГИГАБИТНЫХ ПОРТОВ. ПРИ ЭТОМ ВОЗМОЖНА ПРАКТИЧЕСКИ ЛЮБАЯ КОМБИНАЦИЯ МЕДНЫХ И ОПТИЧЕСКИХ ПОРТОВ. ПИТАНИЕ: НАПРЯЖЕНИЕ ПИТАНИЯ: 220VAC/DC (85-264VAC/77-370VDC) МЕХАНИЧЕСКИЕ ХАРАКТЕРИСТИКИ: РАЗМЕРЫ 482.6 X 44 X 360 ММ КРЕПЛЕНИЕ 19" СТОЙКА КЛАСС ЗАЩИТЫ IP40 ВЕС 10 КГ РАБОЧАЯ ТЕМПЕРАТУРА ОТ -40 ДО +85С ТЕМПЕРАТУРА ХРАНЕНИЯ -40 ДО +85C ВЛАЖНОСТЬ ОТ 5 ДО 95% (БЕЗ КОНДЕНСАТА) MTBF 368000 ЧАСОВ ГАРАНТИЯ 5 ЛЕТ | I27: CT | J27: Kyland Technology Co., Ltd. | K27: 156 | L27: отсутствует | M27: KYLAND | N27: шт | O27: Нотификация | P27: 10052 | Q27: =VLOOKUP(C27,Лист1!$B$1:$N$33,5,0) -> RU0000049917 | R27: =VLOOKUP(C27,Лист1!$B$1:$N$33,6,0) -> 44099 | S27: =VLOOKUP(C27,Лист1!$B$1:$N$33,7,0) -> 44099 | T27: =VLOOKUP(C27,Лист1!$B$1:$N$33,8,0) -> 47848 | U27: =VLOOKUP(C27,Лист1!$B$1:$N$33,9,0) -> 1.9 | V27: =U27*E27 -> 17.1 | W27: 13.5 | X27: =W27+W27*0.05 -> 14.175 | Y27: Декларация о соответствии | AE27: отсутствует | AF27: 10005030/031120/0330735 | AG27: Симанитрон
A28: 44125 | B28: =VLOOKUP(C28,Лист1!$B$1:$N$33,2,0) -> 8517620003 | C28: SICOM3000-2M6T-SC05-HV-S | D28: =VLOOKUP(C28,Лист1!$B$2:$T$45,14,0) -> ПРОМЫШЛЕННЫЕ КОММУТАТОРЫ ДЛЯ УПРАВЛЕНИЯ В СЕТЯХ ETHERNET, НЕ ЛОМ ЭЛЕКТРООБОРУДОВАНИЯ, НЕ ПРЕДНАЗНАЧЕНЫ ДЛЯ НЕГЛАСНОГО ПОЛУЧЕНИЯ ИНФОРМАЦИИ, КОМПЛЕКТУЮЩИЕ ДЛЯ СЕРВЕРОВ И СЕРВЕРНОГО ОБОРУДОВАНИЯ, ГРАЖДАНСКОГО ПРИМЕНЕНИЯ. ПОСТАВЛЯЮТСЯ С клеммными колодками , уголками для крепления в стойку и консольным кабелем. | E28: 2 | F28: 386.75 | G28: =F28*E28 -> 773.5 | H28: =VLOOKUP(C28,Лист1!$B$1:$N$33,4,0) -> SICOM3028GPT-L3G-MB-HV-HV-S - ПРОМЫШЛЕННЫЕ КОММУТАТОРЫ С ШИРОКИМ СПЕКТРОМ СФЕР ПРИМЕНЕНИЯ И МОДУЛЬНЫМ ДИЗАЙНОМ ДЛЯ ПРОСТОТЫ МАСШТАБИРОВАНИЯ И РАСШИРЕНИЯ ФУНКЦИОНАЛА УСТРОЙСТВА. SICOM3028GPT-L3G МОГУТ ИМЕТЬ ДО 28 ГИГАБИТНЫХ ПОРТОВ. ПРИ ЭТОМ ВОЗМОЖНА ПРАКТИЧЕСКИ ЛЮБАЯ КОМБИНАЦИЯ МЕДНЫХ И ОПТИЧЕСКИХ ПОРТОВ. ПИТАНИЕ: НАПРЯЖЕНИЕ ПИТАНИЯ: 220VAC/DC (85-264VAC/77-370VDC) МЕХАНИЧЕСКИЕ ХАРАКТЕРИСТИКИ: РАЗМЕРЫ 482.6 X 44 X 360 ММ КРЕПЛЕНИЕ 19" СТОЙКА КЛАСС ЗАЩИТЫ IP40 ВЕС 10 КГ РАБОЧАЯ ТЕМПЕРАТУРА ОТ -40 ДО +85С ТЕМПЕРАТУРА ХРАНЕНИЯ -40 ДО +85C ВЛАЖНОСТЬ ОТ 5 ДО 95% (БЕЗ КОНДЕНСАТА) MTBF 368000 ЧАСОВ ГАРАНТИЯ 5 ЛЕТ | I28: CT | J28: Kyland Technology Co., Ltd. | K28: 156 | L28: отсутствует | M28: KYLAND | N28: шт | O28: Нотификация | P28: 10052 | Q28: =VLOOKUP(C28,Лист1!$B$1:$N$33,5,0) -> RU0000033118 | R28: =VLOOKUP(C28,Лист1!$B$1:$N$33,6,0) -> 42972 | S28: =VLOOKUP(C28,Лист1!$B$1:$N$33,7,0) -> 42972 | T28: =VLOOKUP(C28,Лист1!$B$1:$N$33,8,0) -> 44369 | U28: =VLOOKUP(C28,Лист1!$B$1:$N$33,9,0) -> 1 | V28: =U28*E28 -> 2 | W28: 3 | X28: =W28+W28*0.05 -> 3.15 | Y28: Декларация о соответствии | Z28: 01191 | AA28: =VLOOKUP(C28,Лист1!$B$1:$N$33,10,0) -> ЕАЭС N RU Д-CN.КА01.В.17403/19 | AB28: =VLOOKUP(C28,Лист1!$B$1:$N$33,11,0) -> 43787 | AC28: =VLOOKUP(C28,Лист1!$B$1:$N$33,12,0) -> 43787 | AD28: =VLOOKUP(C28,Лист1!$B$1:$N$33,13,0) -> 45613 | AE28: отсутствует | AF28: 10005030/031120/0330735 | AG28: Симанитрон
A29: 44125 | B29: =VLOOKUP(C29,Лист1!$B$1:$N$33,2,0) -> 8517620003 | C29: SYM3000A-8T-HV | D29: =VLOOKUP(C29,Лист1!$B$2:$T$45,14,0) -> ПРОМЫШЛЕННЫЕ КОММУТАТОРЫ ДЛЯ УПРАВЛЕНИЯ В СЕТЯХ ETHERNET, НЕ ЛОМ ЭЛЕКТРООБОРУДОВАНИЯ, НЕ ПРЕДНАЗНАЧЕНЫ ДЛЯ НЕГЛАСНОГО ПОЛУЧЕНИЯ ИНФОРМАЦИИ, КОМПЛЕКТУЮЩИЕ ДЛЯ СЕРВЕРОВ И СЕРВЕРНОГО ОБОРУДОВАНИЯ, ГРАЖДАНСКОГО ПРИМЕНЕНИЯ. ПОСТАВЛЯЮТСЯ С клеммными колодками , уголками для крепления в стойку и консольным кабелем. | E29: 10 | F29: 195.07 | G29: =F29*E29 -> 1950.7 | H29: =VLOOKUP(C29,Лист1!$B$1:$N$33,4,0) -> SICOM3028GPT-L3G-MB-HV-HV-S - ПРОМЫШЛЕННЫЕ КОММУТАТОРЫ С ШИРОКИМ СПЕКТРОМ СФЕР ПРИМЕНЕНИЯ И МОДУЛЬНЫМ ДИЗАЙНОМ ДЛЯ ПРОСТОТЫ МАСШТАБИРОВАНИЯ И РАСШИРЕНИЯ ФУНКЦИОНАЛА УСТРОЙСТВА. SICOM3028GPT-L3G МОГУТ ИМЕТЬ ДО 28 ГИГАБИТНЫХ ПОРТОВ. ПРИ ЭТОМ ВОЗМОЖНА ПРАКТИЧЕСКИ ЛЮБАЯ КОМБИНАЦИЯ МЕДНЫХ И ОПТИЧЕСКИХ ПОРТОВ. ПИТАНИЕ: НАПРЯЖЕНИЕ ПИТАНИЯ: 220VAC/DC (85-264VAC/77-370VDC) МЕХАНИЧЕСКИЕ ХАРАКТЕРИСТИКИ: РАЗМЕРЫ 482.6 X 44 X 360 ММ КРЕПЛЕНИЕ 19" СТОЙКА КЛАСС ЗАЩИТЫ IP40 ВЕС 10 КГ РАБОЧАЯ ТЕМПЕРАТУРА ОТ -40 ДО +85С ТЕМПЕРАТУРА ХРАНЕНИЯ -40 ДО +85C ВЛАЖНОСТЬ ОТ 5 ДО 95% (БЕЗ КОНДЕНСАТА) MTBF 368000 ЧАСОВ ГАРАНТИЯ 5 ЛЕТ | I29: CT | J29: Kyland Technology Co., Ltd. | K29: 156 | L29: отсутствует | M29: KYLAND | N29: шт | O29: Нотификация | P29: 10052 | Q29: =VLOOKUP(C29,Лист1!$B$1:$N$33,5,0) -> RU0000049917 | R29: =VLOOKUP(C29,Лист1!$B$1:$N$33,6,0) -> 44099 | S29: =VLOOKUP(C29,Лист1!$B$1:$N$33,7,0) -> 44099 | T29: =VLOOKUP(C29,Лист1!$B$1:$N$33,8,0) -> 47848 | U29: =VLOOKUP(C29,Лист1!$B$1:$N$33,9,0) -> 1.1 | V29: =U29*E29 -> 11 | W29: 15 | X29: =W29+W29*0.05 -> 15.75 | Y29: Декларация о соответствии | Z29: 01191 | AA29: =VLOOKUP(C29,Лист1!$B$1:$N$33,10,0) -> ЕАЭС N RU Д-CN.КА01.В.27192/20 | AB29: =VLOOKUP(C29,Лист1!$B$1:$N$33,11,0) -> 43984 | AC29: =VLOOKUP(C29,Лист1!$B$1:$N$33,12,0) -> 43984 | AD29: =VLOOKUP(C29,Лист1!$B$1:$N$33,13,0) -> 45809 | AE29: отсутствует | AF29: 10005030/031120/0330735 | AG29: Симанитрон
A30: 44125 | B30: =VLOOKUP(C30,Лист1!$B$1:$N$33,2,0) -> 8517620003 | C30: SICOM3009A-8T-L2-L2-S | D30: =VLOOKUP(C30,Лист1!$B$2:$T$45,14,0) -> ПРОМЫШЛЕННЫЕ КОММУТАТОРЫ ДЛЯ УПРАВЛЕНИЯ В СЕТЯХ ETHERNET, НЕ ЛОМ ЭЛЕКТРООБОРУДОВАНИЯ, НЕ ПРЕДНАЗНАЧЕНЫ ДЛЯ НЕГЛАСНОГО ПОЛУЧЕНИЯ ИНФОРМАЦИИ, КОМПЛЕКТУЮЩИЕ ДЛЯ СЕРВЕРОВ И СЕРВЕРНОГО ОБОРУДОВАНИЯ, ГРАЖДАНСКОГО ПРИМЕНЕНИЯ. ПОСТАВЛЯЮТСЯ С клеммными колодками , уголками для крепления в стойку и консольным кабелем. | E30: 2 | F30: 331 | G30: =F30*E30 -> 662 | H30: =VLOOKUP(C30,Лист1!$B$1:$N$33,4,0) -> SICOM3028GPT-L3G-MB-HV-HV-S - ПРОМЫШЛЕННЫЕ КОММУТАТОРЫ С ШИРОКИМ СПЕКТРОМ СФЕР ПРИМЕНЕНИЯ И МОДУЛЬНЫМ ДИЗАЙНОМ ДЛЯ ПРОСТОТЫ МАСШТАБИРОВАНИЯ И РАСШИРЕНИЯ ФУНКЦИОНАЛА УСТРОЙСТВА. SICOM3028GPT-L3G МОГУТ ИМЕТЬ ДО 28 ГИГАБИТНЫХ ПОРТОВ. ПРИ ЭТОМ ВОЗМОЖНА ПРАКТИЧЕСКИ ЛЮБАЯ КОМБИНАЦИЯ МЕДНЫХ И ОПТИЧЕСКИХ ПОРТОВ. ПИТАНИЕ: НАПРЯЖЕНИЕ ПИТАНИЯ: 220VAC/DC (85-264VAC/77-370VDC) МЕХАНИЧЕСКИЕ ХАРАКТЕРИСТИКИ: РАЗМЕРЫ 482.6 X 44 X 360 ММ КРЕПЛЕНИЕ 19" СТОЙКА КЛАСС ЗАЩИТЫ IP40 ВЕС 10 КГ РАБОЧАЯ ТЕМПЕРАТУРА ОТ -40 ДО +85С ТЕМПЕРАТУРА ХРАНЕНИЯ -40 ДО +85C ВЛАЖНОСТЬ ОТ 5 ДО 95% (БЕЗ КОНДЕНСАТА) MTBF 368000 ЧАСОВ ГАРАНТИЯ 5 ЛЕТ | I30: CT | J30: Kyland Technology Co., Ltd. | K30: 156 | L30: отсутствует | M30: KYLAND | N30: шт | O30: Нотификация | P30: 10052 | Q30: =VLOOKUP(C30,Лист1!$B$1:$N$33,5,0) -> RU0000033119 | R30: =VLOOKUP(C30,Лист1!$B$1:$N$33,6,0) -> 42972 | S30: =VLOOKUP(C30,Лист1!$B$1:$N$33,7,0) -> 42972 | T30: =VLOOKUP(C30,Лист1!$B$1:$N$33,8,0) -> 44369 | U30: =VLOOKUP(C30,Лист1!$B$1:$N$33,9,0) -> 0.76 | V30: =U30*E30 -> 1.52 | W30: 2.6 | X30: =W30+W30*0.05 -> 2.73 | Y30: Декларация о соответствии | AE30: отсутствует | AF30: 10005030/031120/0330735 | AG30: Симанитрон
A31: 21.10.2020 с батарейками | B31: =VLOOKUP(C31,Лист1!$B$1:$N$33,2,0) -> 8517620003 | C31: SICOM3024P-4GX16S8T-SC40-HV-HV-S | D31: =VLOOKUP(C31,Лист1!$B$2:$T$45,14,0) -> ПРОМЫШЛЕННЫЕ КОММУТАТОРЫ ДЛЯ УПРАВЛЕНИЯ В СЕТЯХ ETHERNET, НЕ ЛОМ ЭЛЕКТРООБОРУДОВАНИЯ, НЕ ПРЕДНАЗНАЧЕНЫ ДЛЯ НЕГЛАСНОГО ПОЛУЧЕНИЯ ИНФОРМАЦИИ, КОМПЛЕКТУЮЩИЕ ДЛЯ СЕРВЕРОВ И СЕРВЕРНОГО ОБОРУДОВАНИЯ, ГРАЖДАНСКОГО ПРИМЕНЕНИЯ. ПОСТАВЛЯЮТСЯ С клеммными колодками , уголками для крепления в стойку и консольным кабелем. | E31: 9 | F31: 1236.75 | G31: =F31*E31 -> 11130.75 | H31: =VLOOKUP(C31,Лист1!$B$1:$N$33,4,0) -> SICOM3028GPT-L3G-MB-HV-HV-S - ПРОМЫШЛЕННЫЕ КОММУТАТОРЫ С ШИРОКИМ СПЕКТРОМ СФЕР ПРИМЕНЕНИЯ И МОДУЛЬНЫМ ДИЗАЙНОМ ДЛЯ ПРОСТОТЫ МАСШТАБИРОВАНИЯ И РАСШИРЕНИЯ ФУНКЦИОНАЛА УСТРОЙСТВА. SICOM3028GPT-L3G МОГУТ ИМЕТЬ ДО 28 ГИГАБИТНЫХ ПОРТОВ. ПРИ ЭТОМ ВОЗМОЖНА ПРАКТИЧЕСКИ ЛЮБАЯ КОМБИНАЦИЯ МЕДНЫХ И ОПТИЧЕСКИХ ПОРТОВ. ПИТАНИЕ: НАПРЯЖЕНИЕ ПИТАНИЯ: 220VAC/DC (85-264VAC/77-370VDC) МЕХАНИЧЕСКИЕ ХАРАКТЕРИСТИКИ: РАЗМЕРЫ 482.6 X 44 X 360 ММ КРЕПЛЕНИЕ 19" СТОЙКА КЛАСС ЗАЩИТЫ IP40 ВЕС 10 КГ РАБОЧАЯ ТЕМПЕРАТУРА ОТ -40 ДО +85С ТЕМПЕРАТУРА ХРАНЕНИЯ -40 ДО +85C ВЛАЖНОСТЬ ОТ 5 ДО 95% (БЕЗ КОНДЕНСАТА) MTBF 368000 ЧАСОВ ГАРАНТИЯ 5 ЛЕТ | I31: CT | J31: Kyland Technology Co., Ltd. | K31: 156 | L31: отсутствует | M31: KYLAND | N31: шт | O31: Нотификация | P31: 10052 | Q31: =VLOOKUP(C31,Лист1!$B$1:$N$33,5,0) -> RU0000033121 | R31: =VLOOKUP(C31,Лист1!$B$1:$N$33,6,0) -> 42972 | S31: =VLOOKUP(C31,Лист1!$B$1:$N$33,7,0) -> 42972 | T31: =VLOOKUP(C31,Лист1!$B$1:$N$33,8,0) -> 44369 | U31: =VLOOKUP(C31,Лист1!$B$1:$N$33,9,0) -> 4 | V31: =U31*E31 -> 36 | W31: 54 | X31: 61.79 | Y31: Декларация о соответствии | Z31: 01191 | AA31: =VLOOKUP(C31,Лист1!$B$1:$N$33,10,0) -> ЕАЭС N RU Д-CN.КА01.В.17403/19 | AB31: =VLOOKUP(C31,Лист1!$B$1:$N$33,11,0) -> 43787 | AC31: =VLOOKUP(C31,Лист1!$B$1:$N$33,12,0) -> 43787 | AD31: =VLOOKUP(C31,Лист1!$B$1:$N$33,13,0) -> 45613 | AE31: отсутствует | AF31: 10005030/231120/0359603 | AG31: Симанитрон
A32: 21.10.2020 с батарейками | B32: =VLOOKUP(C32,Лист1!$B$1:$N$33,2,0) -> 8517620003 | C32: SICOM3028GPT-L3G-MB-HV-HV-S | D32: =VLOOKUP(C32,Лист1!$B$2:$T$45,14,0) -> ПРОМЫШЛЕННЫЕ КОММУТАТОРЫ ДЛЯ УПРАВЛЕНИЯ В СЕТЯХ ETHERNET, НЕ ЛОМ ЭЛЕКТРООБОРУДОВАНИЯ, НЕ ПРЕДНАЗНАЧЕНЫ ДЛЯ НЕГЛАСНОГО ПОЛУЧЕНИЯ ИНФОРМАЦИИ, КОМПЛЕКТУЮЩИЕ ДЛЯ СЕРВЕРОВ И СЕРВЕРНОГО ОБОРУДОВАНИЯ, ГРАЖДАНСКОГО ПРИМЕНЕНИЯ. ПОСТАВЛЯЮТСЯ С клеммными колодками , уголками для крепления в стойку и консольным кабелем. | E32: 9 | F32: 1162.8 | G32: =F32*E32 -> 10465.2 | H32: =VLOOKUP(C32,Лист1!$B$1:$N$33,4,0) -> SICOM3028GPT-L3G-MB-HV-HV-S - ПРОМЫШЛЕННЫЕ КОММУТАТОРЫ С ШИРОКИМ СПЕКТРОМ СФЕР ПРИМЕНЕНИЯ И МОДУЛЬНЫМ ДИЗАЙНОМ ДЛЯ ПРОСТОТЫ МАСШТАБИРОВАНИЯ И РАСШИРЕНИЯ ФУНКЦИОНАЛА УСТРОЙСТВА. SICOM3028GPT-L3G МОГУТ ИМЕТЬ ДО 28 ГИГАБИТНЫХ ПОРТОВ. ПРИ ЭТОМ ВОЗМОЖНА ПРАКТИЧЕСКИ ЛЮБАЯ КОМБИНАЦИЯ МЕДНЫХ И ОПТИЧЕСКИХ ПОРТОВ. ПИТАНИЕ: НАПРЯЖЕНИЕ ПИТАНИЯ: 220VAC/DC (85-264VAC/77-370VDC) МЕХАНИЧЕСКИЕ ХАРАКТЕРИСТИКИ: РАЗМЕРЫ 482.6 X 44 X 360 ММ КРЕПЛЕНИЕ 19" СТОЙКА КЛАСС ЗАЩИТЫ IP40 ВЕС 10 КГ РАБОЧАЯ ТЕМПЕРАТУРА ОТ -40 ДО +85С ТЕМПЕРАТУРА ХРАНЕНИЯ -40 ДО +85C ВЛАЖНОСТЬ ОТ 5 ДО 95% (БЕЗ КОНДЕНСАТА) MTBF 368000 ЧАСОВ ГАРАНТИЯ 5 ЛЕТ | I32: CT | J32: Kyland Technology Co., Ltd. | K32: 156 | L32: отсутствует | M32: KYLAND | N32: шт | O32: Нотификация | P32: 10052 | Q32: =VLOOKUP(C32,Лист1!$B$1:$N$33,5,0) -> RU0000053245 | R32: =VLOOKUP(C32,Лист1!$B$1:$N$33,6,0) -> 44383 | S32: =VLOOKUP(C32,Лист1!$B$1:$N$33,7,0) -> 44383 | T32: =VLOOKUP(C32,Лист1!$B$1:$N$33,8,0) -> 48213 | U32: =VLOOKUP(C32,Лист1!$B$1:$N$33,9,0) -> 10 | V32: =U32*E32 -> 90 | W32: 65.7 | X32: =W32+W32*0.14 -> 74.898 | Y32: Декларация о соответствии | Z32: 01191 | AA32: =VLOOKUP(C32,Лист1!$B$1:$N$33,10,0) -> ЕАЭС N RU Д-CN.КА01.В.23216/20 | AB32: =VLOOKUP(C32,Лист1!$B$1:$N$33,11,0) -> 43908 | AC32: =VLOOKUP(C32,Лист1!$B$1:$N$33,12,0) -> 43908 | AD32: =VLOOKUP(C32,Лист1!$B$1:$N$33,13,0) -> 45733 | AE32: отсутствует | AF32: 10005030/231120/0359603 | AG32: Симанитрон
A33: 21.10.2020 с батарейками | B33: =VLOOKUP(C33,Лист1!$B$1:$N$33,2,0) -> 8517620003 | C33: SM6.6-4GE-1U-S | D33: =VLOOKUP(C33,Лист1!$B$2:$T$45,14,0) -> ПРОМЫШЛЕННЫЕ КОММУТАТОРЫ ДЛЯ УПРАВЛЕНИЯ В СЕТЯХ ETHERNET, НЕ ЛОМ ЭЛЕКТРООБОРУДОВАНИЯ, НЕ ПРЕДНАЗНАЧЕНЫ ДЛЯ НЕГЛАСНОГО ПОЛУЧЕНИЯ ИНФОРМАЦИИ, КОМПЛЕКТУЮЩИЕ ДЛЯ СЕРВЕРОВ И СЕРВЕРНОГО ОБОРУДОВАНИЯ, ГРАЖДАНСКОГО ПРИМЕНЕНИЯ. ПОСТАВЛЯЮТСЯ С клеммными колодками , уголками для крепления в стойку и консольным кабелем. | E33: 9 | F33: 168.3 | G33: =F33*E33 -> 1514.7 | H33: =VLOOKUP(C33,Лист1!$B$1:$N$33,4,0) -> SICOM3028GPT-L3G-MB-HV-HV-S - ПРОМЫШЛЕННЫЕ КОММУТАТОРЫ С ШИРОКИМ СПЕКТРОМ СФЕР ПРИМЕНЕНИЯ И МОДУЛЬНЫМ ДИЗАЙНОМ ДЛЯ ПРОСТОТЫ МАСШТАБИРОВАНИЯ И РАСШИРЕНИЯ ФУНКЦИОНАЛА УСТРОЙСТВА. SICOM3028GPT-L3G МОГУТ ИМЕТЬ ДО 28 ГИГАБИТНЫХ ПОРТОВ. ПРИ ЭТОМ ВОЗМОЖНА ПРАКТИЧЕСКИ ЛЮБАЯ КОМБИНАЦИЯ МЕДНЫХ И ОПТИЧЕСКИХ ПОРТОВ. ПИТАНИЕ: НАПРЯЖЕНИЕ ПИТАНИЯ: 220VAC/DC (85-264VAC/77-370VDC) МЕХАНИЧЕСКИЕ ХАРАКТЕРИСТИКИ: РАЗМЕРЫ 482.6 X 44 X 360 ММ КРЕПЛЕНИЕ 19" СТОЙКА КЛАСС ЗАЩИТЫ IP40 ВЕС 10 КГ РАБОЧАЯ ТЕМПЕРАТУРА ОТ -40 ДО +85С ТЕМПЕРАТУРА ХРАНЕНИЯ -40 ДО +85C ВЛАЖНОСТЬ ОТ 5 ДО 95% (БЕЗ КОНДЕНСАТА) MTBF 368000 ЧАСОВ ГАРАНТИЯ 5 ЛЕТ | I33: CT | J33: Kyland Technology Co., Ltd. | K33: 156 | L33: отсутствует | M33: KYLAND | N33: шт | O33: Нотификация | P33: 10052 | Q33: =VLOOKUP(C33,Лист1!$B$1:$N$33,5,0) -> RU0000053828 | R33: =VLOOKUP(C33,Лист1!$B$1:$N$33,6,0) -> 44431 | S33: =VLOOKUP(C33,Лист1!$B$1:$N$33,7,0) -> 44431 | T33: =VLOOKUP(C33,Лист1!$B$1:$N$33,8,0) -> 48213 | U33: =VLOOKUP(C33,Лист1!$B$1:$N$33,9,0) -> 0.3 | V33: =U33*E33 -> 2.7 | W33: 2.7 | X33: =W33+W33*0.14 -> 3.078 | Y33: Декларация о соответствии | Z33: 01191 | AE33: отсутствует | AF33: 10005030/231120/0359603 | AG33: Симанитрон
A34: 21.10.2020 с батарейками | B34: =VLOOKUP(C34,Лист1!$B$1:$N$33,2,0) -> 8517620003 | C34: SM6.6-4T-0.5U-S | D34: =VLOOKUP(C34,Лист1!$B$2:$T$45,14,0) -> ПРОМЫШЛЕННЫЕ КОММУТАТОРЫ ДЛЯ УПРАВЛЕНИЯ В СЕТЯХ ETHERNET, НЕ ЛОМ ЭЛЕКТРООБОРУДОВАНИЯ, НЕ ПРЕДНАЗНАЧЕНЫ ДЛЯ НЕГЛАСНОГО ПОЛУЧЕНИЯ ИНФОРМАЦИИ, КОМПЛЕКТУЮЩИЕ ДЛЯ СЕРВЕРОВ И СЕРВЕРНОГО ОБОРУДОВАНИЯ, ГРАЖДАНСКОГО ПРИМЕНЕНИЯ. ПОСТАВЛЯЮТСЯ С клеммными колодками , уголками для крепления в стойку и консольным кабелем. | E34: 9 | F34: 50.15 | G34: =F34*E34 -> 451.35 | H34: =VLOOKUP(C34,Лист1!$B$1:$N$33,4,0) -> SICOM3028GPT-L3G-MB-HV-HV-S - ПРОМЫШЛЕННЫЕ КОММУТАТОРЫ С ШИРОКИМ СПЕКТРОМ СФЕР ПРИМЕНЕНИЯ И МОДУЛЬНЫМ ДИЗАЙНОМ ДЛЯ ПРОСТОТЫ МАСШТАБИРОВАНИЯ И РАСШИРЕНИЯ ФУНКЦИОНАЛА УСТРОЙСТВА. SICOM3028GPT-L3G МОГУТ ИМЕТЬ ДО 28 ГИГАБИТНЫХ ПОРТОВ. ПРИ ЭТОМ ВОЗМОЖНА ПРАКТИЧЕСКИ ЛЮБАЯ КОМБИНАЦИЯ МЕДНЫХ И ОПТИЧЕСКИХ ПОРТОВ. ПИТАНИЕ: НАПРЯЖЕНИЕ ПИТАНИЯ: 220VAC/DC (85-264VAC/77-370VDC) МЕХАНИЧЕСКИЕ ХАРАКТЕРИСТИКИ: РАЗМЕРЫ 482.6 X 44 X 360 ММ КРЕПЛЕНИЕ 19" СТОЙКА КЛАСС ЗАЩИТЫ IP40 ВЕС 10 КГ РАБОЧАЯ ТЕМПЕРАТУРА ОТ -40 ДО +85С ТЕМПЕРАТУРА ХРАНЕНИЯ -40 ДО +85C ВЛАЖНОСТЬ ОТ 5 ДО 95% (БЕЗ КОНДЕНСАТА) MTBF 368000 ЧАСОВ ГАРАНТИЯ 5 ЛЕТ | I34: CT | J34: Kyland Technology Co., Ltd. | K34: 156 | L34: отсутствует | M34: KYLAND | N34: шт | O34: Нотификация | P34: 10052 | Q34: =VLOOKUP(C34,Лист1!$B$1:$N$33,5,0) -> RU0000053828 | R34: =VLOOKUP(C34,Лист1!$B$1:$N$33,6,0) -> 44431 | S34: =VLOOKUP(C34,Лист1!$B$1:$N$33,7,0) -> 44431 | T34: =VLOOKUP(C34,Лист1!$B$1:$N$33,8,0) -> 48213 | U34: =VLOOKUP(C34,Лист1!$B$1:$N$33,9,0) -> 0.3 | V34: =U34*E34 -> 2.7 | W34: 2.7 | X34: =W34+W34*0.14 -> 3.078 | Y34: Декларация о соответствии | Z34: 01191 | AE34: отсутствует | AF34: 10005030/231120/0359603 | AG34: Симанитрон
A35: 21.10.2020 с батарейками | B35: =VLOOKUP(C35,Лист1!$B$1:$N$33,2,0) -> 8517620003 | C35: SM6.6-4M-ST05-0.5U-S | D35: =VLOOKUP(C35,Лист1!$B$2:$T$45,14,0) -> ПРОМЫШЛЕННЫЕ КОММУТАТОРЫ ДЛЯ УПРАВЛЕНИЯ В СЕТЯХ ETHERNET, НЕ ЛОМ ЭЛЕКТРООБОРУДОВАНИЯ, НЕ ПРЕДНАЗНАЧЕНЫ ДЛЯ НЕГЛАСНОГО ПОЛУЧЕНИЯ ИНФОРМАЦИИ, КОМПЛЕКТУЮЩИЕ ДЛЯ СЕРВЕРОВ И СЕРВЕРНОГО ОБОРУДОВАНИЯ, ГРАЖДАНСКОГО ПРИМЕНЕНИЯ. ПОСТАВЛЯЮТСЯ С клеммными колодками , уголками для крепления в стойку и консольным кабелем. | E35: 18 | F35: 224.4 | G35: =F35*E35 -> 4039.2 | H35: =VLOOKUP(C35,Лист1!$B$1:$N$33,4,0) -> SICOM3028GPT-L3G-MB-HV-HV-S - ПРОМЫШЛЕННЫЕ КОММУТАТОРЫ С ШИРОКИМ СПЕКТРОМ СФЕР ПРИМЕНЕНИЯ И МОДУЛЬНЫМ ДИЗАЙНОМ ДЛЯ ПРОСТОТЫ МАСШТАБИРОВАНИЯ И РАСШИРЕНИЯ ФУНКЦИОНАЛА УСТРОЙСТВА. SICOM3028GPT-L3G МОГУТ ИМЕТЬ ДО 28 ГИГАБИТНЫХ ПОРТОВ. ПРИ ЭТОМ ВОЗМОЖНА ПРАКТИЧЕСКИ ЛЮБАЯ КОМБИНАЦИЯ МЕДНЫХ И ОПТИЧЕСКИХ ПОРТОВ. ПИТАНИЕ: НАПРЯЖЕНИЕ ПИТАНИЯ: 220VAC/DC (85-264VAC/77-370VDC) МЕХАНИЧЕСКИЕ ХАРАКТЕРИСТИКИ: РАЗМЕРЫ 482.6 X 44 X 360 ММ КРЕПЛЕНИЕ 19" СТОЙКА КЛАСС ЗАЩИТЫ IP40 ВЕС 10 КГ РАБОЧАЯ ТЕМПЕРАТУРА ОТ -40 ДО +85С ТЕМПЕРАТУРА ХРАНЕНИЯ -40 ДО +85C ВЛАЖНОСТЬ ОТ 5 ДО 95% (БЕЗ КОНДЕНСАТА) MTBF 368000 ЧАСОВ ГАРАНТИЯ 5 ЛЕТ | I35: CT | J35: Kyland Technology Co., Ltd. | K35: 156 | L35: отсутствует | M35: KYLAND | N35: шт | O35: Нотификация | P35: 10052 | Q35: =VLOOKUP(C35,Лист1!$B$1:$N$33,5,0) -> RU0000053828 | R35: =VLOOKUP(C35,Лист1!$B$1:$N$33,6,0) -> 44431 | S35: =VLOOKUP(C35,Лист1!$B$1:$N$33,7,0) -> 44431 | T35: =VLOOKUP(C35,Лист1!$B$1:$N$33,8,0) -> 48213 | U35: =VLOOKUP(C35,Лист1!$B$1:$N$33,9,0) -> 0.3 | V35: =U35*E35 -> 5.4 | W35: 5.4 | X35: =W35+W35*0.14 -> 6.156 | Y35: Декларация о соответствии | Z35: 01191 | AE35: отсутствует | AF35: 10005030/231120/0359603 | AG35: Симанитрон
A36: 44158 | B36: =VLOOKUP(C36,Лист1!$B$1:$N$33,2,0) -> 8517620003 | C36: SYM6000A-8GE-L2-L2 | D36: =VLOOKUP(C36,Лист1!$B$2:$T$45,14,0) -> ПРОМЫШЛЕННЫЕ КОММУТАТОРЫ ДЛЯ УПРАВЛЕНИЯ В СЕТЯХ ETHERNET, НЕ ЛОМ ЭЛЕКТРООБОРУДОВАНИЯ, НЕ ПРЕДНАЗНАЧЕНЫ ДЛЯ НЕГЛАСНОГО ПОЛУЧЕНИЯ ИНФОРМАЦИИ, КОМПЛЕКТУЮЩИЕ ДЛЯ СЕРВЕРОВ И СЕРВЕРНОГО ОБОРУДОВАНИЯ, ГРАЖДАНСКОГО ПРИМЕНЕНИЯ. ПОСТАВЛЯЮТСЯ С клеммными колодками , уголками для крепления в стойку и консольным кабелем. | E36: 6 | F36: 569.07 | G36: =F36*E36 -> 3414.42 | H36: =VLOOKUP(C36,Лист1!$B$1:$N$33,4,0) -> SICOM3028GPT-L3G-MB-HV-HV-S - ПРОМЫШЛЕННЫЕ КОММУТАТОРЫ С ШИРОКИМ СПЕКТРОМ СФЕР ПРИМЕНЕНИЯ И МОДУЛЬНЫМ ДИЗАЙНОМ ДЛЯ ПРОСТОТЫ МАСШТАБИРОВАНИЯ И РАСШИРЕНИЯ ФУНКЦИОНАЛА УСТРОЙСТВА. SICOM3028GPT-L3G МОГУТ ИМЕТЬ ДО 28 ГИГАБИТНЫХ ПОРТОВ. ПРИ ЭТОМ ВОЗМОЖНА ПРАКТИЧЕСКИ ЛЮБАЯ КОМБИНАЦИЯ МЕДНЫХ И ОПТИЧЕСКИХ ПОРТОВ. ПИТАНИЕ: НАПРЯЖЕНИЕ ПИТАНИЯ: 220VAC/DC (85-264VAC/77-370VDC) МЕХАНИЧЕСКИЕ ХАРАКТЕРИСТИКИ: РАЗМЕРЫ 482.6 X 44 X 360 ММ КРЕПЛЕНИЕ 19" СТОЙКА КЛАСС ЗАЩИТЫ IP40 ВЕС 10 КГ РАБОЧАЯ ТЕМПЕРАТУРА ОТ -40 ДО +85С ТЕМПЕРАТУРА ХРАНЕНИЯ -40 ДО +85C ВЛАЖНОСТЬ ОТ 5 ДО 95% (БЕЗ КОНДЕНСАТА) MTBF 368000 ЧАСОВ ГАРАНТИЯ 5 ЛЕТ | I36: CT | J36: Kyland Technology Co., Ltd. | K36: 156 | L36: отсутствует | M36: KYLAND | N36: шт | O36: Нотификация | P36: 10052 | Q36: =VLOOKUP(C36,Лист1!$B$1:$N$33,5,0) -> RU0000049918 | R36: =VLOOKUP(C36,Лист1!$B$1:$N$33,6,0) -> 44099 | S36: =VLOOKUP(C36,Лист1!$B$1:$N$33,7,0) -> 44099 | T36: =VLOOKUP(C36,Лист1!$B$1:$N$33,8,0) -> 47848 | U36: =VLOOKUP(C36,Лист1!$B$1:$N$33,9,0) -> 1.5 | V36: =U36*E36 -> 9 | W36: 9.6 | X36: 11.04 | Y36: Декларация о соответствии | Z36: 01191 | AE36: отсутствует | AF36: 10005030/041220/0376976 | AG36: Симанитрон
